Workbook

Sheet 1 A
J1: ESTADÍSTICA DE GRUPO
F3: ESCUELA PRIMARIA | M3: ESPACIOS A LLENAR POR EL DOCENTE, EL RESTO ES AUTOMATIZADO.
F4: CICLO ESCOLAR 2020-2021 | G4: 2026-2027
C5: GRADO 1º GRUPO " A " | G5: EDADES | I5: AL | J5: 46266
A6: Nº | B6: CURP | C6: NOMBRE DEL ALUMNO | F6: SEXO | G6: DIA | H6: MES | I6: AÑO | J6: FECHA_NAC | K6: EDAD | L6: REPETIDOR | O6: 5 AÑOS | P6: 6 AÑOS | Q6: 7 AÑOS | R6: 8 AÑOS | S6: 9 AÑOS | T6: 10 AÑOS | U6: 11 AÑOS | V6: 12 AÑOS | W6: 13 AÑOS | X6: 14 AÑOS | Y6: 15 AÑOS | Z6: TOTAL
A7: 1 | F7: =MID(B7,11,1) | G7: =MID(B7,9,2) | H7: =MID(B7,7,2) | I7: =MID(B7,5,2)+2000 -> #VALUE! | J7: =DATE(I7,H7,G7) -> #VALUE! | K7: =DATEDIF(J7,$J$5,"Y") -> #VALUE! | L7: NO | N7: NUEVO ING. | O7: =COUNTIFS($F$7:$F$46,"H",$K$7:$K$46,5,$L$7:$L$46,"NO") -> 0 | P7: =COUNTIFS($F$7:$F$46,"H",$K$7:$K$46,6,$L$7:$L$46,"NO") -> 0 | Q7: =COUNTIFS($F$7:$F$46,"H",$K$7:$K$46,7,$L$7:$L$46,"NO") -> 0 | R7: =COUNTIFS($F$7:$F$46,"H",$K$7:$K$46,8,$L$7:$L$46,"NO") -> 0 | S7: =COUNTIFS($F$7:$F$46,"H",$K$7:$K$46,9,$L$7:$L$46,"NO") -> 0 | T7: =COUNTIFS($F$7:$F$46,"H",$K$7:$K$46,10,$L$7:$L$46,"NO") -> 0 | U7: =COUNTIFS($F$7:$F$46,"H",$K$7:$K$46,11,$L$7:$L$46,"NO") -> 0 | V7: =COUNTIFS($F$7:$F$46,"H",$K$7:$K$46,12,$L$7:$L$46,"NO") -> 0 | W7: =COUNTIFS($F$7:$F$46,"H",$K$7:$K$46,13,$L$7:$L$46,"NO") -> 0 | X7: =COUNTIFS($F$7:$F$46,"H",$K$7:$K$46,14,$L$7:$L$46,"NO") -> 0 | Y7: =COUNTIFS($F$7:$F$46,"H",$K$7:$K$46,15,$L$7:$L$46,"NO") -> 0 | Z7: =SUM(O7:Y7) -> 0
A8: 2 | F8: =MID(B8,11,1) | G8: =MID(B8,9,2) | H8: =MID(B8,7,2) | I8: =MID(B8,5,2)+2000 -> #VALUE! | J8: =DATE(I8,H8,G8) -> #VALUE! | K8: =DATEDIF(J8,$J$5,"Y") -> #VALUE! | L8: NO | M8: HOMBRES | N8: REPETIDORES | O8: =COUNTIFS($F$7:$F$46,"H",$K$7:$K$46,5,$L$7:$L$46,"SI") -> 0 | P8: =COUNTIFS($F$7:$F$46,"H",$K$7:$K$46,6,$L$7:$L$46,"SI") -> 0 | Q8: =COUNTIFS($F$7:$F$46,"H",$K$7:$K$46,7,$L$7:$L$46,"SI") -> 0 | R8: =COUNTIFS($F$7:$F$46,"H",$K$7:$K$46,8,$L$7:$L$46,"SI") -> 0 | S8: =COUNTIFS($F$7:$F$46,"H",$K$7:$K$46,9,$L$7:$L$46,"SI") -> 0 | T8: =COUNTIFS($F$7:$F$46,"H",$K$7:$K$46,10,$L$7:$L$46,"SI") -> 0 | U8: =COUNTIFS($F$7:$F$46,"H",$K$7:$K$46,11,$L$7:$L$46,"SI") -> 0 | V8: =COUNTIFS($F$7:$F$46,"H",$K$7:$K$46,12,$L$7:$L$46,"SI") -> 0 | W8: =COUNTIFS($F$7:$F$46,"H",$K$7:$K$46,13,$L$7:$L$46,"SI") -> 0 | X8: =COUNTIFS($F$7:$F$46,"H",$K$7:$K$46,14,$L$7:$L$46,"SI") -> 0 | Y8: =COUNTIFS($F$7:$F$46,"H",$K$7:$K$46,15,$L$7:$L$46,"SI") -> 0 | Z8: =SUM(O8:Y8) -> 0
A9: 3 | F9: =MID(B9,11,1) | G9: =MID(B9,9,2) | H9: =MID(B9,7,2) | I9: =MID(B9,5,2)+2000 -> #VALUE! | J9: =DATE(I9,H9,G9) -> #VALUE! | K9: =DATEDIF(J9,$J$5,"Y") -> #VALUE! | L9: NO | O9: 5 AÑOS | P9: 6 AÑOS | Q9: 7 AÑOS | R9: 8 AÑOS | S9: 9 AÑOS | T9: 10 AÑOS | U9: 11 AÑOS | V9: 12 AÑOS | W9: 13 AÑOS | X9: 14 AÑOS | Y9: 15 AÑOS | Z9: TOTAL
A10: 4 | F10: =MID(B10,11,1) | G10: =MID(B10,9,2) | H10: =MID(B10,7,2) | I10: =MID(B10,5,2)+2000 -> #VALUE! | J10: =DATE(I10,H10,G10) -> #VALUE! | K10: =DATEDIF(J10,$J$5,"Y") -> #VALUE! | L10: NO | N10: NUEVO ING. | O10: =COUNTIFS($F$7:$F$46,"M",$K$7:$K$46,5,$L$7:$L$46,"NO") -> 0 | P10: =COUNTIFS($F$7:$F$46,"M",$K$7:$K$46,6,$L$7:$L$46,"NO") -> 0 | Q10: =COUNTIFS($F$7:$F$46,"M",$K$7:$K$46,7,$L$7:$L$46,"NO") -> 0 | R10: =COUNTIFS($F$7:$F$46,"M",$K$7:$K$46,8,$L$7:$L$46,"NO") -> 0 | S10: =COUNTIFS($F$7:$F$46,"M",$K$7:$K$46,9,$L$7:$L$46,"NO") -> 0 | T10: =COUNTIFS($F$7:$F$46,"M",$K$7:$K$46,10,$L$7:$L$46,"NO") -> 0 | U10: =COUNTIFS($F$7:$F$46,"M",$K$7:$K$46,11,$L$7:$L$46,"NO") -> 0 | V10: =COUNTIFS($F$7:$F$46,"M",$K$7:$K$46,12,$L$7:$L$46,"NO") -> 0 | W10: =COUNTIFS($F$7:$F$46,"M",$K$7:$K$46,13,$L$7:$L$46,"NO") -> 0 | X10: =COUNTIFS($F$7:$F$46,"M",$K$7:$K$46,14,$L$7:$L$46,"NO") -> 0 | Y10: =COUNTIFS($F$7:$F$46,"M",$K$7:$K$46,15,$L$7:$L$46,"NO") -> 0 | Z10: =SUM(O10:Y10) -> 0
A11: 5 | F11: =MID(B11,11,1) | G11: =MID(B11,9,2) | H11: =MID(B11,7,2) | I11: =MID(B11,5,2)+2000 -> #VALUE! | J11: =DATE(I11,H11,G11) -> #VALUE! | K11: =DATEDIF(J11,$J$5,"Y") -> #VALUE! | L11: NO | M11: MUJERES | N11: REPETIDORES | O11: =COUNTIFS($F$7:$F$46,"M",$K$7:$K$46,5,$L$7:$L$46,"SI") -> 0 | P11: =COUNTIFS($F$7:$F$46,"M",$K$7:$K$46,6,$L$7:$L$46,"SI") -> 0 | Q11: =COUNTIFS($F$7:$F$46,"M",$K$7:$K$46,7,$L$7:$L$46,"SI") -> 0 | R11: =COUNTIFS($F$7:$F$46,"M",$K$7:$K$46,8,$L$7:$L$46,"SI") -> 0 | S11: =COUNTIFS($F$7:$F$46,"M",$K$7:$K$46,9,$L$7:$L$46,"SI") -> 0 | T11: =COUNTIFS($F$7:$F$46,"M",$K$7:$K$46,10,$L$7:$L$46,"SI") -> 0 | U11: =COUNTIFS($F$7:$F$46,"M",$K$7:$K$46,11,$L$7:$L$46,"SI") -> 0 | V11: =COUNTIFS($F$7:$F$46,"M",$K$7:$K$46,12,$L$7:$L$46,"SI") -> 0 | W11: =COUNTIFS($F$7:$F$46,"M",$K$7:$K$46,13,$L$7:$L$46,"SI") -> 0 | X11: =COUNTIFS($F$7:$F$46,"M",$K$7:$K$46,14,$L$7:$L$46,"SI") -> 0 | Y11: =COUNTIFS($F$7:$F$46,"M",$K$7:$K$46,15,$L$7:$L$46,"SI") -> 0 | Z11: =SUM(O11:Y11) -> 0
A12: 6 | F12: =MID(B12,11,1) | G12: =MID(B12,9,2) | H12: =MID(B12,7,2) | I12: =MID(B12,5,2)+2000 -> #VALUE! | J12: =DATE(I12,H12,G12) -> #VALUE! | K12: =DATEDIF(J12,$J$5,"Y") -> #VALUE! | L12: NO
A13: 7 | F13: =MID(B13,11,1) | G13: =MID(B13,9,2) | H13: =MID(B13,7,2) | I13: =MID(B13,5,2)+2000 -> #VALUE! | J13: =DATE(I13,H13,G13) -> #VALUE! | K13: =DATEDIF(J13,$J$5,"Y") -> #VALUE! | L13: NO | N13: SUBTOTAL | O13: =SUM(O7:O11) -> 0 | P13: =SUM(P7:P11) -> 0 | Q13: =SUM(Q7:Q11) -> 0 | R13: =SUM(R7:R11) -> 0 | S13: =SUM(S7:S11) -> 0 | T13: =SUM(T7:T11) -> 0 | U13: =SUM(U7:U11) -> 0 | V13: =SUM(V7:V11) -> 0 | ... Y13: =SUM(Y7:Y11) -> 0 | Z13: =SUM(O13:Y13) -> 0
A14: 8 | F14: =MID(B14,11,1) | G14: =MID(B14,9,2) | H14: =MID(B14,7,2) | I14: =MID(B14,5,2)+2000 -> #VALUE! | J14: =DATE(I14,H14,G14) -> #VALUE! | K14: =DATEDIF(J14,$J$5,"Y") -> #VALUE! | L14: NO
A15: 9 | F15: =MID(B15,11,1) | G15: =MID(B15,9,2) | H15: =MID(B15,7,2) | I15: =MID(B15,5,2)+2000 -> #VALUE! | J15: =DATE(I15,H15,G15) -> #VALUE! | K15: =DATEDIF(J15,$J$5,"Y") -> #VALUE! | L15: NO
A16: 10 | F16: =MID(B16,11,1) | G16: =MID(B16,9,2) | H16: =MID(B16,7,2) | I16: =MID(B16,5,2)+2000 -> #VALUE! | J16: =DATE(I16,H16,G16) -> #VALUE! | K16: =DATEDIF(J16,$J$5,"Y") -> #VALUE! | L16: NO
A17: 11 | F17: =MID(B17,11,1) | G17: =MID(B17,9,2) | H17: =MID(B17,7,2) | I17: =MID(B17,5,2)+2000 -> #VALUE! | J17: =DATE(I17,H17,G17) -> #VALUE! | K17: =DATEDIF(J17,$J$5,"Y") -> #VALUE! | L17: NO
A18: 12 | F18: =MID(B18,11,1) | G18: =MID(B18,9,2) | H18: =MID(B18,7,2) | I18: =MID(B18,5,2)+2000 -> #VALUE! | J18: =DATE(I18,H18,G18) -> #VALUE! | K18: =DATEDIF(J18,$J$5,"Y") -> #VALUE! | L18: NO
A19: 13 | F19: =MID(B19,11,1) | G19: =MID(B19,9,2) | H19: =MID(B19,7,2) | I19: =MID(B19,5,2)+2000 -> #VALUE! | J19: =DATE(I19,H19,G19) -> #VALUE! | K19: =DATEDIF(J19,$J$5,"Y") -> #VALUE! | L19: NO
A20: 14 | F20: =MID(B20,11,1) | G20: =MID(B20,9,2) | H20: =MID(B20,7,2) | I20: =MID(B20,5,2)+2000 -> #VALUE! | J20: =DATE(I20,H20,G20) -> #VALUE! | K20: =DATEDIF(J20,$J$5,"Y") -> #VALUE! | L20: NO
A21: 15 | F21: =MID(B21,11,1) | G21: =MID(B21,9,2) | H21: =MID(B21,7,2) | I21: =MID(B21,5,2)+2000 -> #VALUE! | J21: =DATE(I21,H21,G21) -> #VALUE! | K21: =DATEDIF(J21,$J$5,"Y") -> #VALUE! | L21: NO
A22: 16 | F22: =MID(B22,11,1) | G22: =MID(B22,9,2) | H22: =MID(B22,7,2) | I22: =MID(B22,5,2)+2000 -> #VALUE! | J22: =DATE(I22,H22,G22) -> #VALUE! | K22: =DATEDIF(J22,$J$5,"Y") -> #VALUE! | L22: NO
A23: 17 | F23: =MID(B23,11,1) | G23: =MID(B23,9,2) | H23: =MID(B23,7,2) | I23: =MID(B23,5,2)+2000 -> #VALUE! | J23: =DATE(I23,H23,G23) -> #VALUE! | K23: =DATEDIF(J23,$J$5,"Y") -> #VALUE! | L23: NO
A24: 18 | F24: =MID(B24,11,1) | G24: =MID(B24,9,2) | H24: =MID(B24,7,2) | I24: =MID(B24,5,2)+2000 -> #VALUE! | J24: =DATE(I24,H24,G24) -> #VALUE! | K24: =DATEDIF(J24,$J$5,"Y") -> #VALUE! | L24: NO
A25: 19 | F25: =MID(B25,11,1) | G25: =MID(B25,9,2) | H25: =MID(B25,7,2) | I25: =MID(B25,5,2)+2000 -> #VALUE! | J25: =DATE(I25,H25,G25) -> #VALUE! | K25: =DATEDIF(J25,$J$5,"Y") -> #VALUE! | L25: NO
... A41: 35 | F41: =MID(B41,11,1) | G41: =MID(B41,9,2) | H41: =MID(B41,7,2) | I41: =MID(B41,5,2)+2000 -> #VALUE! | J41: =DATE(I41,H41,G41) -> #VALUE! | K41: =DATEDIF(J41,$J$5,"Y") -> #VALUE! | L41: NO
A42: 36 | F42: =MID(B42,11,1) | G42: =MID(B42,9,2)
A43: 37 | F43: =MID(B43,11,1) | G43: =MID(B43,9,2)
A44: 38 | F44: =MID(B44,11,1) | G44: =MID(B44,9,2)
A45: 39 | F45: =MID(B45,11,1) | G45: =MID(B45,9,2)
A46: 40 | F46: =MID(B46,11,1) | G46: =MID(B46,9,2)
J47: MUJERES | K47: =COUNTIF(F7:F46, "M") -> 0
J48: HOMBRES | K48: =COUNTIF(F7:F46,"H") -> 0
J49: TOTAL | K49: =SUM(K47:K48) -> 0

Sheet 1 B
J1: ESTADÍSTICA DE GRUPO
F3: ESCUELA PRIMARIA | M3: ESPACIOS A LLENAR POR EL DOCENTE, EL RESTO ES AUTOMATIZADO.
F4: CICLO ESCOLAR 2026-2027
C5: GRADO 1º GRUPO " B " | G5: EDADES | I5: AL | J5: 46266
A6: Nº | B6: CURP | C6: NOMBRE DEL ALUMNO | F6: SEXO | G6: DIA | H6: MES | I6: AÑO | J6: FECHA_NAC | K6: EDAD | L6: REPETIDOR | O6: 5 AÑOS | P6: 6 AÑOS | Q6: 7 AÑOS | R6: 8 AÑOS | S6: 9 AÑOS | T6: 10 AÑOS | U6: 11 AÑOS | V6: 12 AÑOS | W6: 13 AÑOS | X6: 14 AÑOS | Y6: 15 AÑOS | Z6: TOTAL
A7: 1 | F7: =MID(B7,11,1) | G7: =MID(B7,9,2) | H7: =MID(B7,7,2) | I7: =MID(B7,5,2)+2000 -> #VALUE! | J7: =DATE(I7,H7,G7) -> #VALUE! | K7: =DATEDIF(J7,$J$5,"Y") -> #VALUE! | L7: NO | N7: NUEVO ING. | O7: =COUNTIFS($F$7:$F$46,"H",$K$7:$K$46,5,$L$7:$L$46,"NO") -> 0 | P7: =COUNTIFS($F$7:$F$46,"H",$K$7:$K$46,6,$L$7:$L$46,"NO") -> 0 | Q7: =COUNTIFS($F$7:$F$46,"H",$K$7:$K$46,7,$L$7:$L$46,"NO") -> 0 | R7: =COUNTIFS($F$7:$F$46,"H",$K$7:$K$46,8,$L$7:$L$46,"NO") -> 0 | S7: =COUNTIFS($F$7:$F$46,"H",$K$7:$K$46,9,$L$7:$L$46,"NO") -> 0 | T7: =COUNTIFS($F$7:$F$46,"H",$K$7:$K$46,10,$L$7:$L$46,"NO") -> 0 | U7: =COUNTIFS($F$7:$F$46,"H",$K$7:$K$46,11,$L$7:$L$46,"NO") -> 0 | V7: =COUNTIFS($F$7:$F$46,"H",$K$7:$K$46,12,$L$7:$L$46,"NO") -> 0 | W7: =COUNTIFS($F$7:$F$46,"H",$K$7:$K$46,13,$L$7:$L$46,"NO") -> 0 | X7: =COUNTIFS($F$7:$F$46,"H",$K$7:$K$46,14,$L$7:$L$46,"NO") -> 0 | Y7: =COUNTIFS($F$7:$F$46,"H",$K$7:$K$46,15,$L$7:$L$46,"NO") -> 0 | Z7: =SUM(O7:Y7) -> 0
A8: 2 | F8: =MID(B8,11,1) | G8: =MID(B8,9,2) | H8: =MID(B8,7,2) | I8: =MID(B8,5,2)+2000 -> #VALUE! | J8: =DATE(I8,H8,G8) -> #VALUE! | K8: =DATEDIF(J8,$J$5,"Y") -> #VALUE! | L8: NO | M8: HOMBRES | N8: REPETIDORES | O8: =COUNTIFS($F$7:$F$46,"H",$K$7:$K$46,5,$L$7:$L$46,"SI") -> 0 | P8: =COUNTIFS($F$7:$F$46,"H",$K$7:$K$46,6,$L$7:$L$46,"SI") -> 0 | Q8: =COUNTIFS($F$7:$F$46,"H",$K$7:$K$46,7,$L$7:$L$46,"SI") -> 0 | R8: =COUNTIFS($F$7:$F$46,"H",$K$7:$K$46,8,$L$7:$L$46,"SI") -> 0 | S8: =COUNTIFS($F$7:$F$46,"H",$K$7:$K$46,9,$L$7:$L$46,"SI") -> 0 | T8: =COUNTIFS($F$7:$F$46,"H",$K$7:$K$46,10,$L$7:$L$46,"SI") -> 0 | U8: =COUNTIFS($F$7:$F$46,"H",$K$7:$K$46,11,$L$7:$L$46,"SI") -> 0 | V8: =COUNTIFS($F$7:$F$46,"H",$K$7:$K$46,12,$L$7:$L$46,"SI") -> 0 | W8: =COUNTIFS($F$7:$F$46,"H",$K$7:$K$46,13,$L$7:$L$46,"SI") -> 0 | X8: =COUNTIFS($F$7:$F$46,"H",$K$7:$K$46,14,$L$7:$L$46,"SI") -> 0 | Y8: =COUNTIFS($F$7:$F$46,"H",$K$7:$K$46,15,$L$7:$L$46,"SI") -> 0 | Z8: =SUM(O8:Y8) -> 0
A9: 3 | F9: =MID(B9,11,1) | G9: =MID(B9,9,2) | H9: =MID(B9,7,2) | I9: =MID(B9,5,2)+2000 -> #VALUE! | J9: =DATE(I9,H9,G9) -> #VALUE! | K9: =DATEDIF(J9,$J$5,"Y") -> #VALUE! | L9: NO | O9: 5 AÑOS | P9: 6 AÑOS | Q9: 7 AÑOS | R9: 8 AÑOS | S9: 9 AÑOS | T9: 10 AÑOS | U9: 11 AÑOS | V9: 12 AÑOS | W9: 13 AÑOS | X9: 14 AÑOS | Y9: 15 AÑOS | Z9: TOTAL
A10: 4 | F10: =MID(B10,11,1) | G10: =MID(B10,9,2) | H10: =MID(B10,7,2) | I10: =MID(B10,5,2)+2000 -> #VALUE! | J10: =DATE(I10,H10,G10) -> #VALUE! | K10: =DATEDIF(J10,$J$5,"Y") -> #VALUE! | L10: NO | N10: NUEVO ING. | O10: =COUNTIFS($F$7:$F$46,"M",$K$7:$K$46,5,$L$7:$L$46,"NO") -> 0 | P10: =COUNTIFS($F$7:$F$46,"M",$K$7:$K$46,6,$L$7:$L$46,"NO") -> 0 | Q10: =COUNTIFS($F$7:$F$46,"M",$K$7:$K$46,7,$L$7:$L$46,"NO") -> 0 | R10: =COUNTIFS($F$7:$F$46,"M",$K$7:$K$46,8,$L$7:$L$46,"NO") -> 0 | S10: =COUNTIFS($F$7:$F$46,"M",$K$7:$K$46,9,$L$7:$L$46,"NO") -> 0 | T10: =COUNTIFS($F$7:$F$46,"M",$K$7:$K$46,10,$L$7:$L$46,"NO") -> 0 | U10: =COUNTIFS($F$7:$F$46,"M",$K$7:$K$46,11,$L$7:$L$46,"NO") -> 0 | V10: =COUNTIFS($F$7:$F$46,"M",$K$7:$K$46,12,$L$7:$L$46,"NO") -> 0 | W10: =COUNTIFS($F$7:$F$46,"M",$K$7:$K$46,13,$L$7:$L$46,"NO") -> 0 | X10: =COUNTIFS($F$7:$F$46,"M",$K$7:$K$46,14,$L$7:$L$46,"NO") -> 0 | Y10: =COUNTIFS($F$7:$F$46,"M",$K$7:$K$46,15,$L$7:$L$46,"NO") -> 0 | Z10: =SUM(O10:Y10) -> 0
A11: 5 | F11: =MID(B11,11,1) | G11: =MID(B11,9,2) | H11: =MID(B11,7,2) | I11: =MID(B11,5,2)+2000 -> #VALUE! | J11: =DATE(I11,H11,G11) -> #VALUE! | K11: =DATEDIF(J11,$J$5,"Y") -> #VALUE! | L11: NO | M11: MUJERES | N11: REPETIDORES | O11: =COUNTIFS($F$7:$F$46,"M",$K$7:$K$46,5,$L$7:$L$46,"SI") -> 0 | P11: =COUNTIFS($F$7:$F$46,"M",$K$7:$K$46,6,$L$7:$L$46,"SI") -> 0 | Q11: =COUNTIFS($F$7:$F$46,"M",$K$7:$K$46,7,$L$7:$L$46,"SI") -> 0 | R11: =COUNTIFS($F$7:$F$46,"M",$K$7:$K$46,8,$L$7:$L$46,"SI") -> 0 | S11: =COUNTIFS($F$7:$F$46,"M",$K$7:$K$46,9,$L$7:$L$46,"SI") -> 0 | T11: =COUNTIFS($F$7:$F$46,"M",$K$7:$K$46,10,$L$7:$L$46,"SI") -> 0 | U11: =COUNTIFS($F$7:$F$46,"M",$K$7:$K$46,11,$L$7:$L$46,"SI") -> 0 | V11: =COUNTIFS($F$7:$F$46,"M",$K$7:$K$46,12,$L$7:$L$46,"SI") -> 0 | W11: =COUNTIFS($F$7:$F$46,"M",$K$7:$K$46,13,$L$7:$L$46,"SI") -> 0 | X11: =COUNTIFS($F$7:$F$46,"M",$K$7:$K$46,14,$L$7:$L$46,"SI") -> 0 | Y11: =COUNTIFS($F$7:$F$46,"M",$K$7:$K$46,15,$L$7:$L$46,"SI") -> 0 | Z11: =SUM(O11:Y11) -> 0
A12: 6 | F12: =MID(B12,11,1) | G12: =MID(B12,9,2) | H12: =MID(B12,7,2) | I12: =MID(B12,5,2)+2000 -> #VALUE! | J12: =DATE(I12,H12,G12) -> #VALUE! | K12: =DATEDIF(J12,$J$5,"Y") -> #VALUE! | L12: NO
A13: 7 | F13: =MID(B13,11,1) | G13: =MID(B13,9,2) | H13: =MID(B13,7,2) | I13: =MID(B13,5,2)+2000 -> #VALUE! | J13: =DATE(I13,H13,G13) -> #VALUE! | K13: =DATEDIF(J13,$J$5,"Y") -> #VALUE! | L13: NO | N13: SUBTOTAL | O13: =SUM(O7:O11) -> 0 | P13: =SUM(P7:P11) -> 0 | Q13: =SUM(Q7:Q11) -> 0 | R13: =SUM(R7:R11) -> 0 | S13: =SUM(S7:S11) -> 0 | T13: =SUM(T7:T11) -> 0 | U13: =SUM(U7:U11) -> 0 | V13: =SUM(V7:V11) -> 0 | ... Y13: =SUM(Y7:Y11) -> 0 | Z13: =SUM(O13:Y13) -> 0
A14: 8 | F14: =MID(B14,11,1) | G14: =MID(B14,9,2) | H14: =MID(B14,7,2) | I14: =MID(B14,5,2)+2000 -> #VALUE! | J14: =DATE(I14,H14,G14) -> #VALUE! | K14: =DATEDIF(J14,$J$5,"Y") -> #VALUE! | L14: NO
A15: 9 | F15: =MID(B15,11,1) | G15: =MID(B15,9,2) | H15: =MID(B15,7,2) | I15: =MID(B15,5,2)+2000 -> #VALUE! | J15: =DATE(I15,H15,G15) -> #VALUE! | K15: =DATEDIF(J15,$J$5,"Y") -> #VALUE! | L15: NO
A16: 10 | F16: =MID(B16,11,1) | G16: =MID(B16,9,2) | H16: =MID(B16,7,2) | I16: =MID(B16,5,2)+2000 -> #VALUE! | J16: =DATE(I16,H16,G16) -> #VALUE! | K16: =DATEDIF(J16,$J$5,"Y") -> #VALUE! | L16: NO
A17: 11 | F17: =MID(B17,11,1) | G17: =MID(B17,9,2) | H17: =MID(B17,7,2) | I17: =MID(B17,5,2)+2000 -> #VALUE! | J17: =DATE(I17,H17,G17) -> #VALUE! | K17: =DATEDIF(J17,$J$5,"Y") -> #VALUE! | L17: NO
A18: 12 | F18: =MID(B18,11,1) | G18: =MID(B18,9,2) | H18: =MID(B18,7,2) | I18: =MID(B18,5,2)+2000 -> #VALUE! | J18: =DATE(I18,H18,G18) -> #VALUE! | K18: =DATEDIF(J18,$J$5,"Y") -> #VALUE! | L18: NO
A19: 13 | F19: =MID(B19,11,1) | G19: =MID(B19,9,2) | H19: =MID(B19,7,2) | I19: =MID(B19,5,2)+2000 -> #VALUE! | J19: =DATE(I19,H19,G19) -> #VALUE! | K19: =DATEDIF(J19,$J$5,"Y") -> #VALUE! | L19: NO
A20: 14 | F20: =MID(B20,11,1) | G20: =MID(B20,9,2) | H20: =MID(B20,7,2) | I20: =MID(B20,5,2)+2000 -> #VALUE! | J20: =DATE(I20,H20,G20) -> #VALUE! | K20: =DATEDIF(J20,$J$5,"Y") -> #VALUE! | L20: NO
A21: 15 | F21: =MID(B21,11,1) | G21: =MID(B21,9,2) | H21: =MID(B21,7,2) | I21: =MID(B21,5,2)+2000 -> #VALUE! | J21: =DATE(I21,H21,G21) -> #VALUE! | K21: =DATEDIF(J21,$J$5,"Y") -> #VALUE! | L21: NO
A22: 16 | F22: =MID(B22,11,1) | G22: =MID(B22,9,2) | H22: =MID(B22,7,2) | I22: =MID(B22,5,2)+2000 -> #VALUE! | J22: =DATE(I22,H22,G22) -> #VALUE! | K22: =DATEDIF(J22,$J$5,"Y") -> #VALUE! | L22: NO
A23: 17 | F23: =MID(B23,11,1) | G23: =MID(B23,9,2) | H23: =MID(B23,7,2) | I23: =MID(B23,5,2)+2000 -> #VALUE! | J23: =DATE(I23,H23,G23) -> #VALUE! | K23: =DATEDIF(J23,$J$5,"Y") -> #VALUE! | L23: NO
A24: 18 | F24: =MID(B24,11,1) | G24: =MID(B24,9,2) | H24: =MID(B24,7,2) | I24: =MID(B24,5,2)+2000 -> #VALUE! | J24: =DATE(I24,H24,G24) -> #VALUE! | K24: =DATEDIF(J24,$J$5,"Y") -> #VALUE! | L24: NO
A25: 19 | F25: =MID(B25,11,1) | G25: =MID(B25,9,2) | H25: =MID(B25,7,2) | I25: =MID(B25,5,2)+2000 -> #VALUE! | J25: =DATE(I25,H25,G25) -> #VALUE! | K25: =DATEDIF(J25,$J$5,"Y") -> #VALUE! | L25: NO
... A41: 35 | F41: =MID(B41,11,1) | G41: =MID(B41,9,2) | H41: =MID(B41,7,2) | I41: =MID(B41,5,2)+2000 -> #VALUE! | J41: =DATE(I41,H41,G41) -> #VALUE! | K41: =DATEDIF(J41,$J$5,"Y") -> #VALUE! | L41: NO
A42: 36 | F42: =MID(B42,11,1) | G42: =MID(B42,9,2)
A43: 37 | F43: =MID(B43,11,1) | G43: =MID(B43,9,2)
A44: 38 | F44: =MID(B44,11,1) | G44: =MID(B44,9,2)
A45: 39 | F45: =MID(B45,11,1) | G45: =MID(B45,9,2)
A46: 40 | F46: =MID(B46,11,1) | G46: =MID(B46,9,2)
J47: MUJERES | K47: =COUNTIF(F7:F46, "M") -> 0
J48: HOMBRES | K48: =COUNTIF(F7:F46,"H") -> 0
J49: TOTAL | K49: =SUM(K47:K48) -> 0

Sheet Concen 1ro
J1: ESTADÍSTICA DE GRUPO
F3: ESCUELA PRIMARIA
F4: CICLO ESCOLAR 2026-2027
C5: GRADO 1º | G5: EDADES | I5: AL | J5: 46266
C6: 5 AÑOS | D6: 6 AÑOS | E6: 7 AÑOS | F6: 8 AÑOS | G6: 9 AÑOS | H6: 10 AÑOS | I6: 11 AÑOS | J6: 12 AÑOS | K6: 13 AÑOS | L6: 14 AÑOS | M6: 15 AÑOS | N6: TOTAL
B7: NUEVO ING. | C7: =('1 A'!O7+'1 B'!O7) -> 0 | D7: =('1 A'!P7+'1 B'!P7) -> 0 | E7: =('1 A'!Q7+'1 B'!Q7) -> 0 | F7: =('1 A'!R7+'1 B'!R7) -> 0 | G7: =('1 A'!S7+'1 B'!S7) -> 0 | H7: =('1 A'!T7+'1 B'!T7) -> 0 | I7: =('1 A'!U7+'1 B'!U7) -> 0 | J7: =('1 A'!V7+'1 B'!V7) -> 0 | ... N7: =('1 A'!Z7+'1 B'!Z7) -> 0
A8: HOMBRES | B8: REPETIDORES | C8: =('1 A'!O8+'1 B'!O8) -> 0 | D8: =('1 A'!P8+'1 B'!P8) -> 0 | E8: =('1 A'!Q8+'1 B'!Q8) -> 0 | F8: =('1 A'!R8+'1 B'!R8) -> 0 | G8: =('1 A'!S8+'1 B'!S8) -> 0 | H8: =('1 A'!T8+'1 B'!T8) -> 0 | I8: =('1 A'!U8+'1 B'!U8) -> 0 | J8: =('1 A'!V8+'1 B'!V8) -> 0 | ... N8: =('1 A'!Z8+'1 B'!Z8) -> 0
C9: 5 AÑOS | D9: 6 AÑOS | E9: 7 AÑOS | F9: 8 AÑOS | G9: 9 AÑOS | H9: 10 AÑOS | I9: 11 AÑOS | J9: 12 AÑOS | K9: 13 AÑOS | L9: 14 AÑOS | M9: 15 AÑOS | N9: TOTAL
B10: NUEVO ING. | C10: =('1 A'!O10+'1 B'!O10) -> 0 | D10: =('1 A'!P10+'1 B'!P10) -> 0 | E10: =('1 A'!Q10+'1 B'!Q10) -> 0 | F10: =('1 A'!R10+'1 B'!R10) -> 0 | G10: =('1 A'!S10+'1 B'!S10) -> 0 | H10: =('1 A'!T10+'1 B'!T10) -> 0 | I10: =('1 A'!U10+'1 B'!U10) -> 0 | J10: =('1 A'!V10+'1 B'!V10) -> 0 | ... N10: =('1 A'!Z10+'1 B'!Z10) -> 0
A11: MUJERES | B11: REPETIDORES | C11: =('1 A'!O11+'1 B'!O11) -> 0 | D11: =('1 A'!P11+'1 B'!P11) -> 0 | E11: =('1 A'!Q11+'1 B'!Q11) -> 0 | F11: =('1 A'!R11+'1 B'!R11) -> 0 | G11: =('1 A'!S11+'1 B'!S11) -> 0 | H11: =('1 A'!T11+'1 B'!T11) -> 0 | I11: =('1 A'!U11+'1 B'!U11) -> 0 | J11: =('1 A'!V11+'1 B'!V11) -> 0 | ... N11: =('1 A'!Z11+'1 B'!Z11) -> 0
B13: SUBTOTAL | C13: =('1 A'!O13+'1 B'!O13) -> 0 | D13: =('1 A'!P13+'1 B'!P13) -> 0 | E13: =('1 A'!Q13+'1 B'!Q13) -> 0 | F13: =('1 A'!R13+'1 B'!R13) -> 0 | G13: =('1 A'!S13+'1 B'!S13) -> 0 | H13: =('1 A'!T13+'1 B'!T13) -> 0 | I13: =('1 A'!U13+'1 B'!U13) -> 0 | J13: =('1 A'!V13+'1 B'!V13) -> 0 | ... N13: =('1 A'!Z13+'1 B'!Z13) -> 0

Sheet 2 A
J1: ESTADÍSTICA DE GRUPO
F3: ESCUELA PRIMARIA | M3: ESPACIOS A LLENAR POR EL DOCENTE, EL RESTO ES AUTOMATIZADO.
F4: CICLO ESCOLAR 2026-2027
C5: GRADO 2º GRUPO " A " | G5: EDADES | I5: AL | J5: 46266
A6: Nº | B6: CURP | C6: NOMBRE DEL ALUMNO | F6: SEXO | G6: DIA | H6: MES | I6: AÑO | J6: FECHA_NAC | K6: EDAD | L6: REPETIDOR | O6: 5 AÑOS | P6: 6 AÑOS | Q6: 7 AÑOS | R6: 8 AÑOS | S6: 9 AÑOS | T6: 10 AÑOS | U6: 11 AÑOS | V6: 12 AÑOS | W6: 13 AÑOS | X6: 14 AÑOS | Y6: 15 AÑOS | Z6: TOTAL
A7: 1 | F7: =MID(B7,11,1) | G7: =MID(B7,9,2) | H7: =MID(B7,7,2) | I7: =MID(B7,5,2)+2000 -> #VALUE! | J7: =DATE(I7,H7,G7) -> #VALUE! | K7: =DATEDIF(J7,$J$5,"Y") -> #VALUE! | L7: NO | N7: NUEVO ING. | O7: =COUNTIFS($F$7:$F$46,"H",$K$7:$K$46,5,$L$7:$L$46,"NO") -> 0 | P7: =COUNTIFS($F$7:$F$46,"H",$K$7:$K$46,6,$L$7:$L$46,"NO") -> 0 | Q7: =COUNTIFS($F$7:$F$46,"H",$K$7:$K$46,7,$L$7:$L$46,"NO") -> 0 | R7: =COUNTIFS($F$7:$F$46,"H",$K$7:$K$46,8,$L$7:$L$46,"NO") -> 0 | S7: =COUNTIFS($F$7:$F$46,"H",$K$7:$K$46,9,$L$7:$L$46,"NO") -> 0 | T7: =COUNTIFS($F$7:$F$46,"H",$K$7:$K$46,10,$L$7:$L$46,"NO") -> 0 | U7: =COUNTIFS($F$7:$F$46,"H",$K$7:$K$46,11,$L$7:$L$46,"NO") -> 0 | V7: =COUNTIFS($F$7:$F$46,"H",$K$7:$K$46,12,$L$7:$L$46,"NO") -> 0 | W7: =COUNTIFS($F$7:$F$46,"H",$K$7:$K$46,13,$L$7:$L$46,"NO") -> 0 | X7: =COUNTIFS($F$7:$F$46,"H",$K$7:$K$46,14,$L$7:$L$46,"NO") -> 0 | Y7: =COUNTIFS($F$7:$F$46,"H",$K$7:$K$46,15,$L$7:$L$46,"NO") -> 0 | Z7: =SUM(O7:Y7) -> 0
A8: 2 | F8: =MID(B8,11,1) | G8: =MID(B8,9,2) | H8: =MID(B8,7,2) | I8: =MID(B8,5,2)+2000 -> #VALUE! | J8: =DATE(I8,H8,G8) -> #VALUE! | K8: =DATEDIF(J8,$J$5,"Y") -> #VALUE! | L8: NO | M8: HOMBRES | N8: REPETIDORES | O8: =COUNTIFS($F$7:$F$46,"H",$K$7:$K$46,5,$L$7:$L$46,"SI") -> 0 | P8: =COUNTIFS($F$7:$F$46,"H",$K$7:$K$46,6,$L$7:$L$46,"SI") -> 0 | Q8: =COUNTIFS($F$7:$F$46,"H",$K$7:$K$46,7,$L$7:$L$46,"SI") -> 0 | R8: =COUNTIFS($F$7:$F$46,"H",$K$7:$K$46,8,$L$7:$L$46,"SI") -> 0 | S8: =COUNTIFS($F$7:$F$46,"H",$K$7:$K$46,9,$L$7:$L$46,"SI") -> 0 | T8: =COUNTIFS($F$7:$F$46,"H",$K$7:$K$46,10,$L$7:$L$46,"SI") -> 0 | U8: =COUNTIFS($F$7:$F$46,"H",$K$7:$K$46,11,$L$7:$L$46,"SI") -> 0 | V8: =COUNTIFS($F$7:$F$46,"H",$K$7:$K$46,12,$L$7:$L$46,"SI") -> 0 | W8: =COUNTIFS($F$7:$F$46,"H",$K$7:$K$46,13,$L$7:$L$46,"SI") -> 0 | X8: =COUNTIFS($F$7:$F$46,"H",$K$7:$K$46,14,$L$7:$L$46,"SI") -> 0 | Y8: =COUNTIFS($F$7:$F$46,"H",$K$7:$K$46,15,$L$7:$L$46,"SI") -> 0 | Z8: =SUM(O8:Y8) -> 0
A9: 3 | F9: =MID(B9,11,1) | G9: =MID(B9,9,2) | H9: =MID(B9,7,2) | I9: =MID(B9,5,2)+2000 -> #VALUE! | J9: =DATE(I9,H9,G9) -> #VALUE! | K9: =DATEDIF(J9,$J$5,"Y") -> #VALUE! | L9: NO | O9: 5 AÑOS | P9: 6 AÑOS | Q9: 7 AÑOS | R9: 8 AÑOS | S9: 9 AÑOS | T9: 10 AÑOS | U9: 11 AÑOS | V9: 12 AÑOS | W9: 13 AÑOS | X9: 14 AÑOS | Y9: 15 AÑOS | Z9: TOTAL
A10: 4 | F10: =MID(B10,11,1) | G10: =MID(B10,9,2) | H10: =MID(B10,7,2) | I10: =MID(B10,5,2)+2000 -> #VALUE! | J10: =DATE(I10,H10,G10) -> #VALUE! | K10: =DATEDIF(J10,$J$5,"Y") -> #VALUE! | L10: NO | N10: NUEVO ING. | O10: =COUNTIFS($F$7:$F$46,"M",$K$7:$K$46,5,$L$7:$L$46,"NO") -> 0 | P10: =COUNTIFS($F$7:$F$46,"M",$K$7:$K$46,6,$L$7:$L$46,"NO") -> 0 | Q10: =COUNTIFS($F$7:$F$46,"M",$K$7:$K$46,7,$L$7:$L$46,"NO") -> 0 | R10: =COUNTIFS($F$7:$F$46,"M",$K$7:$K$46,8,$L$7:$L$46,"NO") -> 0 | S10: =COUNTIFS($F$7:$F$46,"M",$K$7:$K$46,9,$L$7:$L$46,"NO") -> 0 | T10: =COUNTIFS($F$7:$F$46,"M",$K$7:$K$46,10,$L$7:$L$46,"NO") -> 0 | U10: =COUNTIFS($F$7:$F$46,"M",$K$7:$K$46,11,$L$7:$L$46,"NO") -> 0 | V10: =COUNTIFS($F$7:$F$46,"M",$K$7:$K$46,12,$L$7:$L$46,"NO") -> 0 | W10: =COUNTIFS($F$7:$F$46,"M",$K$7:$K$46,13,$L$7:$L$46,"NO") -> 0 | X10: =COUNTIFS($F$7:$F$46,"M",$K$7:$K$46,14,$L$7:$L$46,"NO") -> 0 | Y10: =COUNTIFS($F$7:$F$46,"M",$K$7:$K$46,15,$L$7:$L$46,"NO") -> 0 | Z10: =SUM(O10:Y10) -> 0
A11: 5 | F11: =MID(B11,11,1) | G11: =MID(B11,9,2) | H11: =MID(B11,7,2) | I11: =MID(B11,5,2)+2000 -> #VALUE! | J11: =DATE(I11,H11,G11) -> #VALUE! | K11: =DATEDIF(J11,$J$5,"Y") -> #VALUE! | L11: NO | M11: MUJERES | N11: REPETIDORES | O11: =COUNTIFS($F$7:$F$46,"M",$K$7:$K$46,5,$L$7:$L$46,"SI") -> 0 | P11: =COUNTIFS($F$7:$F$46,"M",$K$7:$K$46,6,$L$7:$L$46,"SI") -> 0 | Q11: =COUNTIFS($F$7:$F$46,"M",$K$7:$K$46,7,$L$7:$L$46,"SI") -> 0 | R11: =COUNTIFS($F$7:$F$46,"M",$K$7:$K$46,8,$L$7:$L$46,"SI") -> 0 | S11: =COUNTIFS($F$7:$F$46,"M",$K$7:$K$46,9,$L$7:$L$46,"SI") -> 0 | T11: =COUNTIFS($F$7:$F$46,"M",$K$7:$K$46,10,$L$7:$L$46,"SI") -> 0 | U11: =COUNTIFS($F$7:$F$46,"M",$K$7:$K$46,11,$L$7:$L$46,"SI") -> 0 | V11: =COUNTIFS($F$7:$F$46,"M",$K$7:$K$46,12,$L$7:$L$46,"SI") -> 0 | W11: =COUNTIFS($F$7:$F$46,"M",$K$7:$K$46,13,$L$7:$L$46,"SI") -> 0 | X11: =COUNTIFS($F$7:$F$46,"M",$K$7:$K$46,14,$L$7:$L$46,"SI") -> 0 | Y11: =COUNTIFS($F$7:$F$46,"M",$K$7:$K$46,15,$L$7:$L$46,"SI") -> 0 | Z11: =SUM(O11:Y11) -> 0
A12: 6 | F12: =MID(B12,11,1) | G12: =MID(B12,9,2) | H12: =MID(B12,7,2) | I12: =MID(B12,5,2)+2000 -> #VALUE! | J12: =DATE(I12,H12,G12) -> #VALUE! | K12: =DATEDIF(J12,$J$5,"Y") -> #VALUE! | L12: NO
A13: 7 | F13: =MID(B13,11,1) | G13: =MID(B13,9,2) | H13: =MID(B13,7,2) | I13: =MID(B13,5,2)+2000 -> #VALUE! | J13: =DATE(I13,H13,G13) -> #VALUE! | K13: =DATEDIF(J13,$J$5,"Y") -> #VALUE! | L13: NO | N13: SUBTOTAL | O13: =SUM(O7:O11) -> 0 | P13: =SUM(P7:P11) -> 0 | Q13: =SUM(Q7:Q11) -> 0 | R13: =SUM(R7:R11) -> 0 | S13: =SUM(S7:S11) -> 0 | T13: =SUM(T7:T11) -> 0 | U13: =SUM(U7:U11) -> 0 | V13: =SUM(V7:V11) -> 0 | ... Y13: =SUM(Y7:Y11) -> 0 | Z13: =SUM(O13:Y13) -> 0
A14: 8 | F14: =MID(B14,11,1) | G14: =MID(B14,9,2) | H14: =MID(B14,7,2) | I14: =MID(B14,5,2)+2000 -> #VALUE! | J14: =DATE(I14,H14,G14) -> #VALUE! | K14: =DATEDIF(J14,$J$5,"Y") -> #VALUE! | L14: NO
A15: 9 | F15: =MID(B15,11,1) | G15: =MID(B15,9,2) | H15: =MID(B15,7,2) | I15: =MID(B15,5,2)+2000 -> #VALUE! | J15: =DATE(I15,H15,G15) -> #VALUE! | K15: =DATEDIF(J15,$J$5,"Y") -> #VALUE! | L15: NO
A16: 10 | F16: =MID(B16,11,1) | G16: =MID(B16,9,2) | H16: =MID(B16,7,2) | I16: =MID(B16,5,2)+2000 -> #VALUE! | J16: =DATE(I16,H16,G16) -> #VALUE! | K16: =DATEDIF(J16,$J$5,"Y") -> #VALUE! | L16: NO
A17: 11 | F17: =MID(B17,11,1) | G17: =MID(B17,9,2) | H17: =MID(B17,7,2) | I17: =MID(B17,5,2)+2000 -> #VALUE! | J17: =DATE(I17,H17,G17) -> #VALUE! | K17: =DATEDIF(J17,$J$5,"Y") -> #VALUE! | L17: NO
A18: 12 | F18: =MID(B18,11,1) | G18: =MID(B18,9,2) | H18: =MID(B18,7,2) | I18: =MID(B18,5,2)+2000 -> #VALUE! | J18: =DATE(I18,H18,G18) -> #VALUE! | K18: =DATEDIF(J18,$J$5,"Y") -> #VALUE! | L18: NO
A19: 13 | F19: =MID(B19,11,1) | G19: =MID(B19,9,2) | H19: =MID(B19,7,2) | I19: =MID(B19,5,2)+2000 -> #VALUE! | J19: =DATE(I19,H19,G19) -> #VALUE! | K19: =DATEDIF(J19,$J$5,"Y") -> #VALUE! | L19: NO
A20: 14 | F20: =MID(B20,11,1) | G20: =MID(B20,9,2) | H20: =MID(B20,7,2) | I20: =MID(B20,5,2)+2000 -> #VALUE! | J20: =DATE(I20,H20,G20) -> #VALUE! | K20: =DATEDIF(J20,$J$5,"Y") -> #VALUE! | L20: NO
A21: 15 | F21: =MID(B21,11,1) | G21: =MID(B21,9,2) | H21: =MID(B21,7,2) | I21: =MID(B21,5,2)+2000 -> #VALUE! | J21: =DATE(I21,H21,G21) -> #VALUE! | K21: =DATEDIF(J21,$J$5,"Y") -> #VALUE! | L21: NO
A22: 16 | F22: =MID(B22,11,1) | G22: =MID(B22,9,2) | H22: =MID(B22,7,2) | I22: =MID(B22,5,2)+2000 -> #VALUE! | J22: =DATE(I22,H22,G22) -> #VALUE! | K22: =DATEDIF(J22,$J$5,"Y") -> #VALUE! | L22: NO
A23: 17 | F23: =MID(B23,11,1) | G23: =MID(B23,9,2) | H23: =MID(B23,7,2) | I23: =MID(B23,5,2)+2000 -> #VALUE! | J23: =DATE(I23,H23,G23) -> #VALUE! | K23: =DATEDIF(J23,$J$5,"Y") -> #VALUE! | L23: NO
A24: 18 | F24: =MID(B24,11,1) | G24: =MID(B24,9,2) | H24: =MID(B24,7,2) | I24: =MID(B24,5,2)+2000 -> #VALUE! | J24: =DATE(I24,H24,G24) -> #VALUE! | K24: =DATEDIF(J24,$J$5,"Y") -> #VALUE! | L24: NO
A25: 19 | F25: =MID(B25,11,1) | G25: =MID(B25,9,2) | H25: =MID(B25,7,2) | I25: =MID(B25,5,2)+2000 -> #VALUE! | J25: =DATE(I25,H25,G25) -> #VALUE! | K25: =DATEDIF(J25,$J$5,"Y") -> #VALUE! | L25: NO
... A41: 35 | F41: =MID(B41,11,1) | G41: =MID(B41,9,2) | H41: =MID(B41,7,2) | I41: =MID(B41,5,2)+2000 -> #VALUE! | J41: =DATE(I41,H41,G41) -> #VALUE! | K41: =DATEDIF(J41,$J$5,"Y") -> #VALUE! | L41: NO
A42: 36 | F42: =MID(B42,11,1) | G42: =MID(B42,9,2)
A43: 37 | F43: =MID(B43,11,1) | G43: =MID(B43,9,2)
A44: 38 | F44: =MID(B44,11,1) | G44: =MID(B44,9,2)
A45: 39 | F45: =MID(B45,11,1) | G45: =MID(B45,9,2)
A46: 40 | F46: =MID(B46,11,1) | G46: =MID(B46,9,2)
J47: MUJERES | K47: =COUNTIF(F7:F46, "M") -> 0
J48: HOMBRES | K48: =COUNTIF(F7:F46,"H") -> 0
J49: TOTAL | K49: =SUM(K47:K48) -> 0

Sheet 2 B
J1: ESTADÍSTICA DE GRUPO
F3: ESCUELA PRIMARIA | M3: ESPACIOS A LLENAR POR EL DOCENTE, EL RESTO ES AUTOMATIZADO.
F4: CICLO ESCOLAR 2026-2027
C5: GRADO 2º GRUPO " B " | G5: EDADES | I5: AL | J5: 46266
A6: Nº | B6: CURP | C6: NOMBRE DEL ALUMNO | F6: SEXO | G6: DIA | H6: MES | I6: AÑO | J6: FECHA_NAC | K6: EDAD | L6: REPETIDOR | O6: 5 AÑOS | P6: 6 AÑOS | Q6: 7 AÑOS | R6: 8 AÑOS | S6: 9 AÑOS | T6: 10 AÑOS | U6: 11 AÑOS | V6: 12 AÑOS | W6: 13 AÑOS | X6: 14 AÑOS | Y6: 15 AÑOS | Z6: TOTAL
A7: 1 | F7: =MID(B7,11,1) | G7: =MID(B7,9,2) | H7: =MID(B7,7,2) | I7: =MID(B7,5,2)+2000 -> #VALUE! | J7: =DATE(I7,H7,G7) -> #VALUE! | K7: =DATEDIF(J7,$J$5,"Y") -> #VALUE! | L7: NO | N7: NUEVO ING. | O7: =COUNTIFS($F$7:$F$46,"H",$K$7:$K$46,5,$L$7:$L$46,"NO") -> 0 | P7: =COUNTIFS($F$7:$F$46,"H",$K$7:$K$46,6,$L$7:$L$46,"NO") -> 0 | Q7: =COUNTIFS($F$7:$F$46,"H",$K$7:$K$46,7,$L$7:$L$46,"NO") -> 0 | R7: =COUNTIFS($F$7:$F$46,"H",$K$7:$K$46,8,$L$7:$L$46,"NO") -> 0 | S7: =COUNTIFS($F$7:$F$46,"H",$K$7:$K$46,9,$L$7:$L$46,"NO") -> 0 | T7: =COUNTIFS($F$7:$F$46,"H",$K$7:$K$46,10,$L$7:$L$46,"NO") -> 0 | U7: =COUNTIFS($F$7:$F$46,"H",$K$7:$K$46,11,$L$7:$L$46,"NO") -> 0 | V7: =COUNTIFS($F$7:$F$46,"H",$K$7:$K$46,12,$L$7:$L$46,"NO") -> 0 | W7: =COUNTIFS($F$7:$F$46,"H",$K$7:$K$46,13,$L$7:$L$46,"NO") -> 0 | X7: =COUNTIFS($F$7:$F$46,"H",$K$7:$K$46,14,$L$7:$L$46,"NO") -> 0 | Y7: =COUNTIFS($F$7:$F$46,"H",$K$7:$K$46,15,$L$7:$L$46,"NO") -> 0 | Z7: =SUM(O7:Y7) -> 0
A8: 2 | F8: =MID(B8,11,1) | G8: =MID(B8,9,2) | H8: =MID(B8,7,2) | I8: =MID(B8,5,2)+2000 -> #VALUE! | J8: =DATE(I8,H8,G8) -> #VALUE! | K8: =DATEDIF(J8,$J$5,"Y") -> #VALUE! | L8: NO | M8: HOMBRES | N8: REPETIDORES | O8: =COUNTIFS($F$7:$F$46,"H",$K$7:$K$46,5,$L$7:$L$46,"SI") -> 0 | P8: =COUNTIFS($F$7:$F$46,"H",$K$7:$K$46,6,$L$7:$L$46,"SI") -> 0 | Q8: =COUNTIFS($F$7:$F$46,"H",$K$7:$K$46,7,$L$7:$L$46,"SI") -> 0 | R8: =COUNTIFS($F$7:$F$46,"H",$K$7:$K$46,8,$L$7:$L$46,"SI") -> 0 | S8: =COUNTIFS($F$7:$F$46,"H",$K$7:$K$46,9,$L$7:$L$46,"SI") -> 0 | T8: =COUNTIFS($F$7:$F$46,"H",$K$7:$K$46,10,$L$7:$L$46,"SI") -> 0 | U8: =COUNTIFS($F$7:$F$46,"H",$K$7:$K$46,11,$L$7:$L$46,"SI") -> 0 | V8: =COUNTIFS($F$7:$F$46,"H",$K$7:$K$46,12,$L$7:$L$46,"SI") -> 0 | W8: =COUNTIFS($F$7:$F$46,"H",$K$7:$K$46,13,$L$7:$L$46,"SI") -> 0 | X8: =COUNTIFS($F$7:$F$46,"H",$K$7:$K$46,14,$L$7:$L$46,"SI") -> 0 | Y8: =COUNTIFS($F$7:$F$46,"H",$K$7:$K$46,15,$L$7:$L$46,"SI") -> 0 | Z8: =SUM(O8:Y8) -> 0
A9: 3 | F9: =MID(B9,11,1) | G9: =MID(B9,9,2) | H9: =MID(B9,7,2) | I9: =MID(B9,5,2)+2000 -> #VALUE! | J9: =DATE(I9,H9,G9) -> #VALUE! | K9: =DATEDIF(J9,$J$5,"Y") -> #VALUE! | L9: NO | O9: 5 AÑOS | P9: 6 AÑOS | Q9: 7 AÑOS | R9: 8 AÑOS | S9: 9 AÑOS | T9: 10 AÑOS | U9: 11 AÑOS | V9: 12 AÑOS | W9: 13 AÑOS | X9: 14 AÑOS | Y9: 15 AÑOS | Z9: TOTAL
A10: 4 | F10: =MID(B10,11,1) | G10: =MID(B10,9,2) | H10: =MID(B10,7,2) | I10: =MID(B10,5,2)+2000 -> #VALUE! | J10: =DATE(I10,H10,G10) -> #VALUE! | K10: =DATEDIF(J10,$J$5,"Y") -> #VALUE! | L10: NO | N10: NUEVO ING. | O10: =COUNTIFS($F$7:$F$46,"M",$K$7:$K$46,5,$L$7:$L$46,"NO") -> 0 | P10: =COUNTIFS($F$7:$F$46,"M",$K$7:$K$46,6,$L$7:$L$46,"NO") -> 0 | Q10: =COUNTIFS($F$7:$F$46,"M",$K$7:$K$46,7,$L$7:$L$46,"NO") -> 0 | R10: =COUNTIFS($F$7:$F$46,"M",$K$7:$K$46,8,$L$7:$L$46,"NO") -> 0 | S10: =COUNTIFS($F$7:$F$46,"M",$K$7:$K$46,9,$L$7:$L$46,"NO") -> 0 | T10: =COUNTIFS($F$7:$F$46,"M",$K$7:$K$46,10,$L$7:$L$46,"NO") -> 0 | U10: =COUNTIFS($F$7:$F$46,"M",$K$7:$K$46,11,$L$7:$L$46,"NO") -> 0 | V10: =COUNTIFS($F$7:$F$46,"M",$K$7:$K$46,12,$L$7:$L$46,"NO") -> 0 | W10: =COUNTIFS($F$7:$F$46,"M",$K$7:$K$46,13,$L$7:$L$46,"NO") -> 0 | X10: =COUNTIFS($F$7:$F$46,"M",$K$7:$K$46,14,$L$7:$L$46,"NO") -> 0 | Y10: =COUNTIFS($F$7:$F$46,"M",$K$7:$K$46,15,$L$7:$L$46,"NO") -> 0 | Z10: =SUM(O10:Y10) -> 0
A11: 5 | F11: =MID(B11,11,1) | G11: =MID(B11,9,2) | H11: =MID(B11,7,2) | I11: =MID(B11,5,2)+2000 -> #VALUE! | J11: =DATE(I11,H11,G11) -> #VALUE! | K11: =DATEDIF(J11,$J$5,"Y") -> #VALUE! | L11: NO | M11: MUJERES | N11: REPETIDORES | O11: =COUNTIFS($F$7:$F$46,"M",$K$7:$K$46,5,$L$7:$L$46,"SI") -> 0 | P11: =COUNTIFS($F$7:$F$46,"M",$K$7:$K$46,6,$L$7:$L$46,"SI") -> 0 | Q11: =COUNTIFS($F$7:$F$46,"M",$K$7:$K$46,7,$L$7:$L$46,"SI") -> 0 | R11: =COUNTIFS($F$7:$F$46,"M",$K$7:$K$46,8,$L$7:$L$46,"SI") -> 0 | S11: =COUNTIFS($F$7:$F$46,"M",$K$7:$K$46,9,$L$7:$L$46,"SI") -> 0 | T11: =COUNTIFS($F$7:$F$46,"M",$K$7:$K$46,10,$L$7:$L$46,"SI") -> 0 | U11: =COUNTIFS($F$7:$F$46,"M",$K$7:$K$46,11,$L$7:$L$46,"SI") -> 0 | V11: =COUNTIFS($F$7:$F$46,"M",$K$7:$K$46,12,$L$7:$L$46,"SI") -> 0 | W11: =COUNTIFS($F$7:$F$46,"M",$K$7:$K$46,13,$L$7:$L$46,"SI") -> 0 | X11: =COUNTIFS($F$7:$F$46,"M",$K$7:$K$46,14,$L$7:$L$46,"SI") -> 0 | Y11: =COUNTIFS($F$7:$F$46,"M",$K$7:$K$46,15,$L$7:$L$46,"SI") -> 0 | Z11: =SUM(O11:Y11) -> 0
A12: 6 | F12: =MID(B12,11,1) | G12: =MID(B12,9,2) | H12: =MID(B12,7,2) | I12: =MID(B12,5,2)+2000 -> #VALUE! | J12: =DATE(I12,H12,G12) -> #VALUE! | K12: =DATEDIF(J12,$J$5,"Y") -> #VALUE! | L12: NO
A13: 7 | F13: =MID(B13,11,1) | G13: =MID(B13,9,2) | H13: =MID(B13,7,2) | I13: =MID(B13,5,2)+2000 -> #VALUE! | J13: =DATE(I13,H13,G13) -> #VALUE! | K13: =DATEDIF(J13,$J$5,"Y") -> #VALUE! | L13: NO | N13: SUBTOTAL | O13: =SUM(O7:O11) -> 0 | P13: =SUM(P7:P11) -> 0 | Q13: =SUM(Q7:Q11) -> 0 | R13: =SUM(R7:R11) -> 0 | S13: =SUM(S7:S11) -> 0 | T13: =SUM(T7:T11) -> 0 | U13: =SUM(U7:U11) -> 0 | V13: =SUM(V7:V11) -> 0 | ... Y13: =SUM(Y7:Y11) -> 0 | Z13: =SUM(O13:Y13) -> 0
A14: 8 | F14: =MID(B14,11,1) | G14: =MID(B14,9,2) | H14: =MID(B14,7,2) | I14: =MID(B14,5,2)+2000 -> #VALUE! | J14: =DATE(I14,H14,G14) -> #VALUE! | K14: =DATEDIF(J14,$J$5,"Y") -> #VALUE! | L14: NO
A15: 9 | F15: =MID(B15,11,1) | G15: =MID(B15,9,2) | H15: =MID(B15,7,2) | I15: =MID(B15,5,2)+2000 -> #VALUE! | J15: =DATE(I15,H15,G15) -> #VALUE! | K15: =DATEDIF(J15,$J$5,"Y") -> #VALUE! | L15: NO
A16: 10 | F16: =MID(B16,11,1) | G16: =MID(B16,9,2) | H16: =MID(B16,7,2) | I16: =MID(B16,5,2)+2000 -> #VALUE! | J16: =DATE(I16,H16,G16) -> #VALUE! | K16: =DATEDIF(J16,$J$5,"Y") -> #VALUE! | L16: NO
A17: 11 | F17: =MID(B17,11,1) | G17: =MID(B17,9,2) | H17: =MID(B17,7,2) | I17: =MID(B17,5,2)+2000 -> #VALUE! | J17: =DATE(I17,H17,G17) -> #VALUE! | K17: =DATEDIF(J17,$J$5,"Y") -> #VALUE! | L17: NO
A18: 12 | F18: =MID(B18,11,1) | G18: =MID(B18,9,2) | H18: =MID(B18,7,2) | I18: =MID(B18,5,2)+2000 -> #VALUE! | J18: =DATE(I18,H18,G18) -> #VALUE! | K18: =DATEDIF(J18,$J$5,"Y") -> #VALUE! | L18: NO
A19: 13 | F19: =MID(B19,11,1) | G19: =MID(B19,9,2) | H19: =MID(B19,7,2) | I19: =MID(B19,5,2)+2000 -> #VALUE! | J19: =DATE(I19,H19,G19) -> #VALUE! | K19: =DATEDIF(J19,$J$5,"Y") -> #VALUE! | L19: NO
A20: 14 | F20: =MID(B20,11,1) | G20: =MID(B20,9,2) | H20: =MID(B20,7,2) | I20: =MID(B20,5,2)+2000 -> #VALUE! | J20: =DATE(I20,H20,G20) -> #VALUE! | K20: =DATEDIF(J20,$J$5,"Y") -> #VALUE! | L20: NO
A21: 15 | F21: =MID(B21,11,1) | G21: =MID(B21,9,2) | H21: =MID(B21,7,2) | I21: =MID(B21,5,2)+2000 -> #VALUE! | J21: =DATE(I21,H21,G21) -> #VALUE! | K21: =DATEDIF(J21,$J$5,"Y") -> #VALUE! | L21: NO
A22: 16 | F22: =MID(B22,11,1) | G22: =MID(B22,9,2) | H22: =MID(B22,7,2) | I22: =MID(B22,5,2)+2000 -> #VALUE! | J22: =DATE(I22,H22,G22) -> #VALUE! | K22: =DATEDIF(J22,$J$5,"Y") -> #VALUE! | L22: NO
A23: 17 | F23: =MID(B23,11,1) | G23: =MID(B23,9,2) | H23: =MID(B23,7,2) | I23: =MID(B23,5,2)+2000 -> #VALUE! | J23: =DATE(I23,H23,G23) -> #VALUE! | K23: =DATEDIF(J23,$J$5,"Y") -> #VALUE! | L23: NO
A24: 18 | F24: =MID(B24,11,1) | G24: =MID(B24,9,2) | H24: =MID(B24,7,2) | I24: =MID(B24,5,2)+2000 -> #VALUE! | J24: =DATE(I24,H24,G24) -> #VALUE! | K24: =DATEDIF(J24,$J$5,"Y") -> #VALUE! | L24: NO
A25: 19 | F25: =MID(B25,11,1) | G25: =MID(B25,9,2) | H25: =MID(B25,7,2) | I25: =MID(B25,5,2)+2000 -> #VALUE! | J25: =DATE(I25,H25,G25) -> #VALUE! | K25: =DATEDIF(J25,$J$5,"Y") -> #VALUE! | L25: NO
... A41: 35 | F41: =MID(B41,11,1) | G41: =MID(B41,9,2) | H41: =MID(B41,7,2) | I41: =MID(B41,5,2)+2000 -> #VALUE! | J41: =DATE(I41,H41,G41) -> #VALUE! | K41: =DATEDIF(J41,$J$5,"Y") -> #VALUE! | L41: NO
A42: 36 | F42: =MID(B42,11,1) | G42: =MID(B42,9,2)
A43: 37 | F43: =MID(B43,11,1) | G43: =MID(B43,9,2)
A44: 38 | F44: =MID(B44,11,1) | G44: =MID(B44,9,2)
A45: 39 | F45: =MID(B45,11,1) | G45: =MID(B45,9,2)
A46: 40 | F46: =MID(B46,11,1) | G46: =MID(B46,9,2)
J47: MUJERES | K47: =COUNTIF(F7:F46, "M") -> 0
J48: HOMBRES | K48: =COUNTIF(F7:F46,"H") -> 0
J49: TOTAL | K49: =SUM(K47:K48) -> 0

Sheet Concen 2do.
J1: ESTADÍSTICA DE GRUPO
F3: ESCUELA PRIMARIA
F4: CICLO ESCOLAR 2026-2027
C5: GRADO 2º | G5: EDADES | I5: AL | J5: 46266
C6: 5 AÑOS | D6: 6 AÑOS | E6: 7 AÑOS | F6: 8 AÑOS | G6: 9 AÑOS | H6: 10 AÑOS | I6: 11 AÑOS | J6: 12 AÑOS | K6: 13 AÑOS | L6: 14 AÑOS | M6: 15 AÑOS | N6: TOTAL
B7: NUEVO ING. | C7: =('2 A'!O7+'2 B'!O7) -> 0 | D7: =('2 A'!P7+'2 B'!P7) -> 0 | E7: =('2 A'!Q7+'2 B'!Q7) -> 0 | F7: =('2 A'!R7+'2 B'!R7) -> 0 | G7: =('2 A'!S7+'2 B'!S7) -> 0 | H7: =('2 A'!T7+'2 B'!T7) -> 0 | I7: =('2 A'!U7+'2 B'!U7) -> 0 | J7: =('2 A'!V7+'2 B'!V7) -> 0 | ... N7: =('2 A'!Z7+'2 B'!Z7) -> 0
A8: HOMBRES | B8: REPETIDORES | C8: =('2 A'!O8+'2 B'!O8) -> 0 | D8: =('2 A'!P8+'2 B'!P8) -> 0 | E8: =('2 A'!Q8+'2 B'!Q8) -> 0 | F8: =('2 A'!R8+'2 B'!R8) -> 0 | G8: =('2 A'!S8+'2 B'!S8) -> 0 | H8: =('2 A'!T8+'2 B'!T8) -> 0 | I8: =('2 A'!U8+'2 B'!U8) -> 0 | J8: =('2 A'!V8+'2 B'!V8) -> 0 | ... N8: =('2 A'!Z8+'2 B'!Z8) -> 0
C9: 5 AÑOS | D9: 6 AÑOS | E9: 7 AÑOS | F9: 8 AÑOS | G9: 9 AÑOS | H9: 10 AÑOS | I9: 11 AÑOS | J9: 12 AÑOS | K9: 13 AÑOS | L9: 14 AÑOS | M9: 15 AÑOS | N9: TOTAL
B10: NUEVO ING. | C10: =('2 A'!O10+'2 B'!O10) -> 0 | D10: =('2 A'!P10+'2 B'!P10) -> 0 | E10: =('2 A'!Q10+'2 B'!Q10) -> 0 | F10: =('2 A'!R10+'2 B'!R10) -> 0 | G10: =('2 A'!S10+'2 B'!S10) -> 0 | H10: =('2 A'!T10+'2 B'!T10) -> 0 | I10: =('2 A'!U10+'2 B'!U10) -> 0 | J10: =('2 A'!V10+'2 B'!V10) -> 0 | ... N10: =('2 A'!Z10+'2 B'!Z10) -> 0
A11: MUJERES | B11: REPETIDORES | C11: =('2 A'!O11+'2 B'!O11) -> 0 | D11: =('2 A'!P11+'2 B'!P11) -> 0 | E11: =('2 A'!Q11+'2 B'!Q11) -> 0 | F11: =('2 A'!R11+'2 B'!R11) -> 0 | G11: =('2 A'!S11+'2 B'!S11) -> 0 | H11: =('2 A'!T11+'2 B'!T11) -> 0 | I11: =('2 A'!U11+'2 B'!U11) -> 0 | J11: =('2 A'!V11+'2 B'!V11) -> 0 | ... N11: =('2 A'!Z11+'2 B'!Z11) -> 0
B13: SUBTOTAL | C13: =('2 A'!O13+'2 B'!O13) -> 0 | D13: =('2 A'!P13+'2 B'!P13) -> 0 | E13: =('2 A'!Q13+'2 B'!Q13) -> 0 | F13: =('2 A'!R13+'2 B'!R13) -> 0 | G13: =('2 A'!S13+'2 B'!S13) -> 0 | H13: =('2 A'!T13+'2 B'!T13) -> 0 | I13: =('2 A'!U13+'2 B'!U13) -> 0 | J13: =('2 A'!V13+'2 B'!V13) -> 0 | ... N13: =('2 A'!Z13+'2 B'!Z13) -> 0

Sheet 3 A 
J1: ESTADÍSTICA DE GRUPO
F3: ESCUELA PRIMARIA | M3: ESPACIOS A LLENAR POR EL DOCENTE, EL RESTO ES AUTOMATIZADO.
F4: CICLO ESCOLAR 2026-2027
C5: GRADO 3º GRUPO " A " | G5: EDADES | I5: AL | J5: 46266
A6: Nº | B6: CURP | C6: NOMBRE DEL ALUMNO | F6: SEXO | G6: DIA | H6: MES | I6: AÑO | J6: FECHA_NAC | K6: EDAD | L6: REPETIDOR | O6: 5 AÑOS | P6: 6 AÑOS | Q6: 7 AÑOS | R6: 8 AÑOS | S6: 9 AÑOS | T6: 10 AÑOS | U6: 11 AÑOS | V6: 12 AÑOS | W6: 13 AÑOS | X6: 14 AÑOS | Y6: 15 AÑOS | Z6: TOTAL
A7: 1 | F7: =MID(B7,11,1) | G7: =MID(B7,9,2) | H7: =MID(B7,7,2) | I7: =MID(B7,5,2)+2000 -> #VALUE! | J7: =DATE(I7,H7,G7) -> #VALUE! | K7: =DATEDIF(J7,$J$5,"Y") -> #VALUE! | L7: NO | N7: NUEVO ING. | O7: =COUNTIFS($F$7:$F$46,"H",$K$7:$K$46,5,$L$7:$L$46,"NO") -> 0 | P7: =COUNTIFS($F$7:$F$46,"H",$K$7:$K$46,6,$L$7:$L$46,"NO") -> 0 | Q7: =COUNTIFS($F$7:$F$46,"H",$K$7:$K$46,7,$L$7:$L$46,"NO") -> 0 | R7: =COUNTIFS($F$7:$F$46,"H",$K$7:$K$46,8,$L$7:$L$46,"NO") -> 0 | S7: =COUNTIFS($F$7:$F$46,"H",$K$7:$K$46,9,$L$7:$L$46,"NO") -> 0 | T7: =COUNTIFS($F$7:$F$46,"H",$K$7:$K$46,10,$L$7:$L$46,"NO") -> 0 | U7: =COUNTIFS($F$7:$F$46,"H",$K$7:$K$46,11,$L$7:$L$46,"NO") -> 0 | V7: =COUNTIFS($F$7:$F$46,"H",$K$7:$K$46,12,$L$7:$L$46,"NO") -> 0 | W7: =COUNTIFS($F$7:$F$46,"H",$K$7:$K$46,13,$L$7:$L$46,"NO") -> 0 | X7: =COUNTIFS($F$7:$F$46,"H",$K$7:$K$46,14,$L$7:$L$46,"NO") -> 0 | Y7: =COUNTIFS($F$7:$F$46,"H",$K$7:$K$46,15,$L$7:$L$46,"NO") -> 0 | Z7: =SUM(O7:Y7) -> 0
A8: 2 | F8: =MID(B8,11,1) | G8: =MID(B8,9,2) | H8: =MID(B8,7,2) | I8: =MID(B8,5,2)+2000 -> #VALUE! | J8: =DATE(I8,H8,G8) -> #VALUE! | K8: =DATEDIF(J8,$J$5,"Y") -> #VALUE! | L8: NO | M8: HOMBRES | N8: REPETIDORES | O8: =COUNTIFS($F$7:$F$46,"H",$K$7:$K$46,5,$L$7:$L$46,"SI") -> 0 | P8: =COUNTIFS($F$7:$F$46,"H",$K$7:$K$46,6,$L$7:$L$46,"SI") -> 0 | Q8: =COUNTIFS($F$7:$F$46,"H",$K$7:$K$46,7,$L$7:$L$46,"SI") -> 0 | R8: =COUNTIFS($F$7:$F$46,"H",$K$7:$K$46,8,$L$7:$L$46,"SI") -> 0 | S8: =COUNTIFS($F$7:$F$46,"H",$K$7:$K$46,9,$L$7:$L$46,"SI") -> 0 | T8: =COUNTIFS($F$7:$F$46,"H",$K$7:$K$46,10,$L$7:$L$46,"SI") -> 0 | U8: =COUNTIFS($F$7:$F$46,"H",$K$7:$K$46,11,$L$7:$L$46,"SI") -> 0 | V8: =COUNTIFS($F$7:$F$46,"H",$K$7:$K$46,12,$L$7:$L$46,"SI") -> 0 | W8: =COUNTIFS($F$7:$F$46,"H",$K$7:$K$46,13,$L$7:$L$46,"SI") -> 0 | X8: =COUNTIFS($F$7:$F$46,"H",$K$7:$K$46,14,$L$7:$L$46,"SI") -> 0 | Y8: =COUNTIFS($F$7:$F$46,"H",$K$7:$K$46,15,$L$7:$L$46,"SI") -> 0 | Z8: =SUM(O8:Y8) -> 0
A9: 3 | F9: =MID(B9,11,1) | G9: =MID(B9,9,2) | H9: =MID(B9,7,2) | I9: =MID(B9,5,2)+2000 -> #VALUE! | J9: =DATE(I9,H9,G9) -> #VALUE! | K9: =DATEDIF(J9,$J$5,"Y") -> #VALUE! | L9: NO | O9: 5 AÑOS | P9: 6 AÑOS | Q9: 7 AÑOS | R9: 8 AÑOS | S9: 9 AÑOS | T9: 10 AÑOS | U9: 11 AÑOS | V9: 12 AÑOS | W9: 13 AÑOS | X9: 14 AÑOS | Y9: 15 AÑOS | Z9: TOTAL
A10: 4 | F10: =MID(B10,11,1) | G10: =MID(B10,9,2) | H10: =MID(B10,7,2) | I10: =MID(B10,5,2)+2000 -> #VALUE! | J10: =DATE(I10,H10,G10) -> #VALUE! | K10: =DATEDIF(J10,$J$5,"Y") -> #VALUE! | L10: NO | N10: NUEVO ING. | O10: =COUNTIFS($F$7:$F$46,"M",$K$7:$K$46,5,$L$7:$L$46,"NO") -> 0 | P10: =COUNTIFS($F$7:$F$46,"M",$K$7:$K$46,6,$L$7:$L$46,"NO") -> 0 | Q10: =COUNTIFS($F$7:$F$46,"M",$K$7:$K$46,7,$L$7:$L$46,"NO") -> 0 | R10: =COUNTIFS($F$7:$F$46,"M",$K$7:$K$46,8,$L$7:$L$46,"NO") -> 0 | S10: =COUNTIFS($F$7:$F$46,"M",$K$7:$K$46,9,$L$7:$L$46,"NO") -> 0 | T10: =COUNTIFS($F$7:$F$46,"M",$K$7:$K$46,10,$L$7:$L$46,"NO") -> 0 | U10: =COUNTIFS($F$7:$F$46,"M",$K$7:$K$46,11,$L$7:$L$46,"NO") -> 0 | V10: =COUNTIFS($F$7:$F$46,"M",$K$7:$K$46,12,$L$7:$L$46,"NO") -> 0 | W10: =COUNTIFS($F$7:$F$46,"M",$K$7:$K$46,13,$L$7:$L$46,"NO") -> 0 | X10: =COUNTIFS($F$7:$F$46,"M",$K$7:$K$46,14,$L$7:$L$46,"NO") -> 0 | Y10: =COUNTIFS($F$7:$F$46,"M",$K$7:$K$46,15,$L$7:$L$46,"NO") -> 0 | Z10: =SUM(O10:Y10) -> 0
A11: 5 | F11: =MID(B11,11,1) | G11: =MID(B11,9,2) | H11: =MID(B11,7,2) | I11: =MID(B11,5,2)+2000 -> #VALUE! | J11: =DATE(I11,H11,G11) -> #VALUE! | K11: =DATEDIF(J11,$J$5,"Y") -> #VALUE! | L11: NO | M11: MUJERES | N11: REPETIDORES | O11: =COUNTIFS($F$7:$F$46,"M",$K$7:$K$46,5,$L$7:$L$46,"SI") -> 0 | P11: =COUNTIFS($F$7:$F$46,"M",$K$7:$K$46,6,$L$7:$L$46,"SI") -> 0 | Q11: =COUNTIFS($F$7:$F$46,"M",$K$7:$K$46,7,$L$7:$L$46,"SI") -> 0 | R11: =COUNTIFS($F$7:$F$46,"M",$K$7:$K$46,8,$L$7:$L$46,"SI") -> 0 | S11: =COUNTIFS($F$7:$F$46,"M",$K$7:$K$46,9,$L$7:$L$46,"SI") -> 0 | T11: =COUNTIFS($F$7:$F$46,"M",$K$7:$K$46,10,$L$7:$L$46,"SI") -> 0 | U11: =COUNTIFS($F$7:$F$46,"M",$K$7:$K$46,11,$L$7:$L$46,"SI") -> 0 | V11: =COUNTIFS($F$7:$F$46,"M",$K$7:$K$46,12,$L$7:$L$46,"SI") -> 0 | W11: =COUNTIFS($F$7:$F$46,"M",$K$7:$K$46,13,$L$7:$L$46,"SI") -> 0 | X11: =COUNTIFS($F$7:$F$46,"M",$K$7:$K$46,14,$L$7:$L$46,"SI") -> 0 | Y11: =COUNTIFS($F$7:$F$46,"M",$K$7:$K$46,15,$L$7:$L$46,"SI") -> 0 | Z11: =SUM(O11:Y11) -> 0
A12: 6 | F12: =MID(B12,11,1) | G12: =MID(B12,9,2) | H12: =MID(B12,7,2) | I12: =MID(B12,5,2)+2000 -> #VALUE! | J12: =DATE(I12,H12,G12) -> #VALUE! | K12: =DATEDIF(J12,$J$5,"Y") -> #VALUE! | L12: NO
A13: 7 | F13: =MID(B13,11,1) | G13: =MID(B13,9,2) | H13: =MID(B13,7,2) | I13: =MID(B13,5,2)+2000 -> #VALUE! | J13: =DATE(I13,H13,G13) -> #VALUE! | K13: =DATEDIF(J13,$J$5,"Y") -> #VALUE! | L13: NO | N13: SUBTOTAL | O13: =SUM(O7:O11) -> 0 | P13: =SUM(P7:P11) -> 0 | Q13: =SUM(Q7:Q11) -> 0 | R13: =SUM(R7:R11) -> 0 | S13: =SUM(S7:S11) -> 0 | T13: =SUM(T7:T11) -> 0 | U13: =SUM(U7:U11) -> 0 | V13: =SUM(V7:V11) -> 0 | ... Y13: =SUM(Y7:Y11) -> 0 | Z13: =SUM(O13:Y13) -> 0
A14: 8 | F14: =MID(B14,11,1) | G14: =MID(B14,9,2) | H14: =MID(B14,7,2) | I14: =MID(B14,5,2)+2000 -> #VALUE! | J14: =DATE(I14,H14,G14) -> #VALUE! | K14: =DATEDIF(J14,$J$5,"Y") -> #VALUE! | L14: NO
A15: 9 | F15: =MID(B15,11,1) | G15: =MID(B15,9,2) | H15: =MID(B15,7,2) | I15: =MID(B15,5,2)+2000 -> #VALUE! | J15: =DATE(I15,H15,G15) -> #VALUE! | K15: =DATEDIF(J15,$J$5,"Y") -> #VALUE! | L15: NO
A16: 10 | F16: =MID(B16,11,1) | G16: =MID(B16,9,2) | H16: =MID(B16,7,2) | I16: =MID(B16,5,2)+2000 -> #VALUE! | J16: =DATE(I16,H16,G16) -> #VALUE! | K16: =DATEDIF(J16,$J$5,"Y") -> #VALUE! | L16: NO
A17: 11 | F17: =MID(B17,11,1) | G17: =MID(B17,9,2) | H17: =MID(B17,7,2) | I17: =MID(B17,5,2)+2000 -> #VALUE! | J17: =DATE(I17,H17,G17) -> #VALUE! | K17: =DATEDIF(J17,$J$5,"Y") -> #VALUE! | L17: NO
A18: 12 | F18: =MID(B18,11,1) | G18: =MID(B18,9,2) | H18: =MID(B18,7,2) | I18: =MID(B18,5,2)+2000 -> #VALUE! | J18: =DATE(I18,H18,G18) -> #VALUE! | K18: =DATEDIF(J18,$J$5,"Y") -> #VALUE! | L18: NO
A19: 13 | F19: =MID(B19,11,1) | G19: =MID(B19,9,2) | H19: =MID(B19,7,2) | I19: =MID(B19,5,2)+2000 -> #VALUE! | J19: =DATE(I19,H19,G19) -> #VALUE! | K19: =DATEDIF(J19,$J$5,"Y") -> #VALUE! | L19: NO
A20: 14 | F20: =MID(B20,11,1) | G20: =MID(B20,9,2) | H20: =MID(B20,7,2) | I20: =MID(B20,5,2)+2000 -> #VALUE! | J20: =DATE(I20,H20,G20) -> #VALUE! | K20: =DATEDIF(J20,$J$5,"Y") -> #VALUE! | L20: NO
A21: 15 | F21: =MID(B21,11,1) | G21: =MID(B21,9,2) | H21: =MID(B21,7,2) | I21: =MID(B21,5,2)+2000 -> #VALUE! | J21: =DATE(I21,H21,G21) -> #VALUE! | K21: =DATEDIF(J21,$J$5,"Y") -> #VALUE! | L21: NO
A22: 16 | F22: =MID(B22,11,1) | G22: =MID(B22,9,2) | H22: =MID(B22,7,2) | I22: =MID(B22,5,2)+2000 -> #VALUE! | J22: =DATE(I22,H22,G22) -> #VALUE! | K22: =DATEDIF(J22,$J$5,"Y") -> #VALUE! | L22: NO
A23: 17 | F23: =MID(B23,11,1) | G23: =MID(B23,9,2) | H23: =MID(B23,7,2) | I23: =MID(B23,5,2)+2000 -> #VALUE! | J23: =DATE(I23,H23,G23) -> #VALUE! | K23: =DATEDIF(J23,$J$5,"Y") -> #VALUE! | L23: NO
A24: 18 | F24: =MID(B24,11,1) | G24: =MID(B24,9,2) | H24: =MID(B24,7,2) | I24: =MID(B24,5,2)+2000 -> #VALUE! | J24: =DATE(I24,H24,G24) -> #VALUE! | K24: =DATEDIF(J24,$J$5,"Y") -> #VALUE! | L24: NO
A25: 19 | F25: =MID(B25,11,1) | G25: =MID(B25,9,2) | H25: =MID(B25,7,2) | I25: =MID(B25,5,2)+2000 -> #VALUE! | J25: =DATE(I25,H25,G25) -> #VALUE! | K25: =DATEDIF(J25,$J$5,"Y") -> #VALUE! | L25: NO
... A41: 35 | F41: =MID(B41,11,1) | G41: =MID(B41,9,2) | H41: =MID(B41,7,2) | I41: =MID(B41,5,2)+2000 -> #VALUE! | J41: =DATE(I41,H41,G41) -> #VALUE! | K41: =DATEDIF(J41,$J$5,"Y") -> #VALUE! | L41: NO
A42: 36 | F42: =MID(B42,11,1) | G42: =MID(B42,9,2)
A43: 37 | F43: =MID(B43,11,1) | G43: =MID(B43,9,2)
A44: 38 | F44: =MID(B44,11,1) | G44: =MID(B44,9,2)
A45: 39 | F45: =MID(B45,11,1) | G45: =MID(B45,9,2)
A46: 40 | F46: =MID(B46,11,1) | G46: =MID(B46,9,2)
J47: MUJERES | K47: =COUNTIF(F7:F46, "M") -> 0
J48: HOMBRES | K48: =COUNTIF(F7:F46,"H") -> 0
J49: TOTAL | K49: =SUM(K47:K48) -> 0

Sheet 3 B
J1: ESTADÍSTICA DE GRUPO
F3: ESCUELA PRIMARIA | M3: ESPACIOS A LLENAR POR EL DOCENTE, EL RESTO ES AUTOMATIZADO.
F4: CICLO ESCOLAR 2026-2027
C5: GRADO 3º GRUPO " B " | G5: EDADES | I5: AL | J5: 46266
A6: Nº | B6: CURP | C6: NOMBRE DEL ALUMNO | F6: SEXO | G6: DIA | H6: MES | I6: AÑO | J6: FECHA_NAC | K6: EDAD | L6: REPETIDOR | O6: 5 AÑOS | P6: 6 AÑOS | Q6: 7 AÑOS | R6: 8 AÑOS | S6: 9 AÑOS | T6: 10 AÑOS | U6: 11 AÑOS | V6: 12 AÑOS | W6: 13 AÑOS | X6: 14 AÑOS | Y6: 15 AÑOS | Z6: TOTAL
A7: 1 | F7: =MID(B7,11,1) | G7: =MID(B7,9,2) | H7: =MID(B7,7,2) | I7: =MID(B7,5,2)+2000 -> #VALUE! | J7: =DATE(I7,H7,G7) -> #VALUE! | K7: =DATEDIF(J7,$J$5,"Y") -> #VALUE! | L7: NO | N7: NUEVO ING. | O7: =COUNTIFS($F$7:$F$46,"H",$K$7:$K$46,5,$L$7:$L$46,"NO") -> 0 | P7: =COUNTIFS($F$7:$F$46,"H",$K$7:$K$46,6,$L$7:$L$46,"NO") -> 0 | Q7: =COUNTIFS($F$7:$F$46,"H",$K$7:$K$46,7,$L$7:$L$46,"NO") -> 0 | R7: =COUNTIFS($F$7:$F$46,"H",$K$7:$K$46,8,$L$7:$L$46,"NO") -> 0 | S7: =COUNTIFS($F$7:$F$46,"H",$K$7:$K$46,9,$L$7:$L$46,"NO") -> 0 | T7: =COUNTIFS($F$7:$F$46,"H",$K$7:$K$46,10,$L$7:$L$46,"NO") -> 0 | U7: =COUNTIFS($F$7:$F$46,"H",$K$7:$K$46,11,$L$7:$L$46,"NO") -> 0 | V7: =COUNTIFS($F$7:$F$46,"H",$K$7:$K$46,12,$L$7:$L$46,"NO") -> 0 | W7: =COUNTIFS($F$7:$F$46,"H",$K$7:$K$46,13,$L$7:$L$46,"NO") -> 0 | X7: =COUNTIFS($F$7:$F$46,"H",$K$7:$K$46,14,$L$7:$L$46,"NO") -> 0 | Y7: =COUNTIFS($F$7:$F$46,"H",$K$7:$K$46,15,$L$7:$L$46,"NO") -> 0 | Z7: =SUM(O7:Y7) -> 0
A8: 2 | F8: =MID(B8,11,1) | G8: =MID(B8,9,2) | H8: =MID(B8,7,2) | I8: =MID(B8,5,2)+2000 -> #VALUE! | J8: =DATE(I8,H8,G8) -> #VALUE! | K8: =DATEDIF(J8,$J$5,"Y") -> #VALUE! | L8: NO | M8: HOMBRES | N8: REPETIDORES | O8: =COUNTIFS($F$7:$F$46,"H",$K$7:$K$46,5,$L$7:$L$46,"SI") -> 0 | P8: =COUNTIFS($F$7:$F$46,"H",$K$7:$K$46,6,$L$7:$L$46,"SI") -> 0 | Q8: =COUNTIFS($F$7:$F$46,"H",$K$7:$K$46,7,$L$7:$L$46,"SI") -> 0 | R8: =COUNTIFS($F$7:$F$46,"H",$K$7:$K$46,8,$L$7:$L$46,"SI") -> 0 | S8: =COUNTIFS($F$7:$F$46,"H",$K$7:$K$46,9,$L$7:$L$46,"SI") -> 0 | T8: =COUNTIFS($F$7:$F$46,"H",$K$7:$K$46,10,$L$7:$L$46,"SI") -> 0 | U8: =COUNTIFS($F$7:$F$46,"H",$K$7:$K$46,11,$L$7:$L$46,"SI") -> 0 | V8: =COUNTIFS($F$7:$F$46,"H",$K$7:$K$46,12,$L$7:$L$46,"SI") -> 0 | W8: =COUNTIFS($F$7:$F$46,"H",$K$7:$K$46,13,$L$7:$L$46,"SI") -> 0 | X8: =COUNTIFS($F$7:$F$46,"H",$K$7:$K$46,14,$L$7:$L$46,"SI") -> 0 | Y8: =COUNTIFS($F$7:$F$46,"H",$K$7:$K$46,15,$L$7:$L$46,"SI") -> 0 | Z8: =SUM(O8:Y8) -> 0
A9: 3 | F9: =MID(B9,11,1) | G9: =MID(B9,9,2) | H9: =MID(B9,7,2) | I9: =MID(B9,5,2)+2000 -> #VALUE! | J9: =DATE(I9,H9,G9) -> #VALUE! | K9: =DATEDIF(J9,$J$5,"Y") -> #VALUE! | L9: NO | O9: 5 AÑOS | P9: 6 AÑOS | Q9: 7 AÑOS | R9: 8 AÑOS | S9: 9 AÑOS | T9: 10 AÑOS | U9: 11 AÑOS | V9: 12 AÑOS | W9: 13 AÑOS | X9: 14 AÑOS | Y9: 15 AÑOS | Z9: TOTAL
A10: 4 | F10: =MID(B10,11,1) | G10: =MID(B10,9,2) | H10: =MID(B10,7,2) | I10: =MID(B10,5,2)+2000 -> #VALUE! | J10: =DATE(I10,H10,G10) -> #VALUE! | K10: =DATEDIF(J10,$J$5,"Y") -> #VALUE! | L10: NO | N10: NUEVO ING. | O10: =COUNTIFS($F$7:$F$46,"M",$K$7:$K$46,5,$L$7:$L$46,"NO") -> 0 | P10: =COUNTIFS($F$7:$F$46,"M",$K$7:$K$46,6,$L$7:$L$46,"NO") -> 0 | Q10: =COUNTIFS($F$7:$F$46,"M",$K$7:$K$46,7,$L$7:$L$46,"NO") -> 0 | R10: =COUNTIFS($F$7:$F$46,"M",$K$7:$K$46,8,$L$7:$L$46,"NO") -> 0 | S10: =COUNTIFS($F$7:$F$46,"M",$K$7:$K$46,9,$L$7:$L$46,"NO") -> 0 | T10: =COUNTIFS($F$7:$F$46,"M",$K$7:$K$46,10,$L$7:$L$46,"NO") -> 0 | U10: =COUNTIFS($F$7:$F$46,"M",$K$7:$K$46,11,$L$7:$L$46,"NO") -> 0 | V10: =COUNTIFS($F$7:$F$46,"M",$K$7:$K$46,12,$L$7:$L$46,"NO") -> 0 | W10: =COUNTIFS($F$7:$F$46,"M",$K$7:$K$46,13,$L$7:$L$46,"NO") -> 0 | X10: =COUNTIFS($F$7:$F$46,"M",$K$7:$K$46,14,$L$7:$L$46,"NO") -> 0 | Y10: =COUNTIFS($F$7:$F$46,"M",$K$7:$K$46,15,$L$7:$L$46,"NO") -> 0 | Z10: =SUM(O10:Y10) -> 0
A11: 5 | F11: =MID(B11,11,1) | G11: =MID(B11,9,2) | H11: =MID(B11,7,2) | I11: =MID(B11,5,2)+2000 -> #VALUE! | J11: =DATE(I11,H11,G11) -> #VALUE! | K11: =DATEDIF(J11,$J$5,"Y") -> #VALUE! | L11: NO | M11: MUJERES | N11: REPETIDORES | O11: =COUNTIFS($F$7:$F$46,"M",$K$7:$K$46,5,$L$7:$L$46,"SI") -> 0 | P11: =COUNTIFS($F$7:$F$46,"M",$K$7:$K$46,6,$L$7:$L$46,"SI") -> 0 | Q11: =COUNTIFS($F$7:$F$46,"M",$K$7:$K$46,7,$L$7:$L$46,"SI") -> 0 | R11: =COUNTIFS($F$7:$F$46,"M",$K$7:$K$46,8,$L$7:$L$46,"SI") -> 0 | S11: =COUNTIFS($F$7:$F$46,"M",$K$7:$K$46,9,$L$7:$L$46,"SI") -> 0 | T11: =COUNTIFS($F$7:$F$46,"M",$K$7:$K$46,10,$L$7:$L$46,"SI") -> 0 | U11: =COUNTIFS($F$7:$F$46,"M",$K$7:$K$46,11,$L$7:$L$46,"SI") -> 0 | V11: =COUNTIFS($F$7:$F$46,"M",$K$7:$K$46,12,$L$7:$L$46,"SI") -> 0 | W11: =COUNTIFS($F$7:$F$46,"M",$K$7:$K$46,13,$L$7:$L$46,"SI") -> 0 | X11: =COUNTIFS($F$7:$F$46,"M",$K$7:$K$46,14,$L$7:$L$46,"SI") -> 0 | Y11: =COUNTIFS($F$7:$F$46,"M",$K$7:$K$46,15,$L$7:$L$46,"SI") -> 0 | Z11: =SUM(O11:Y11) -> 0
A12: 6 | F12: =MID(B12,11,1) | G12: =MID(B12,9,2) | H12: =MID(B12,7,2) | I12: =MID(B12,5,2)+2000 -> #VALUE! | J12: =DATE(I12,H12,G12) -> #VALUE! | K12: =DATEDIF(J12,$J$5,"Y") -> #VALUE! | L12: NO
A13: 7 | F13: =MID(B13,11,1) | G13: =MID(B13,9,2) | H13: =MID(B13,7,2) | I13: =MID(B13,5,2)+2000 -> #VALUE! | J13: =DATE(I13,H13,G13) -> #VALUE! | K13: =DATEDIF(J13,$J$5,"Y") -> #VALUE! | L13: NO | N13: SUBTOTAL | O13: =SUM(O7:O11) -> 0 | P13: =SUM(P7:P11) -> 0 | Q13: =SUM(Q7:Q11) -> 0 | R13: =SUM(R7:R11) -> 0 | S13: =SUM(S7:S11) -> 0 | T13: =SUM(T7:T11) -> 0 | U13: =SUM(U7:U11) -> 0 | V13: =SUM(V7:V11) -> 0 | ... Y13: =SUM(Y7:Y11) -> 0 | Z13: =SUM(O13:Y13) -> 0
A14: 8 | F14: =MID(B14,11,1) | G14: =MID(B14,9,2) | H14: =MID(B14,7,2) | I14: =MID(B14,5,2)+2000 -> #VALUE! | J14: =DATE(I14,H14,G14) -> #VALUE! | K14: =DATEDIF(J14,$J$5,"Y") -> #VALUE! | L14: NO
A15: 9 | F15: =MID(B15,11,1) | G15: =MID(B15,9,2) | H15: =MID(B15,7,2) | I15: =MID(B15,5,2)+2000 -> #VALUE! | J15: =DATE(I15,H15,G15) -> #VALUE! | K15: =DATEDIF(J15,$J$5,"Y") -> #VALUE! | L15: NO
A16: 10 | F16: =MID(B16,11,1) | G16: =MID(B16,9,2) | H16: =MID(B16,7,2) | I16: =MID(B16,5,2)+2000 -> #VALUE! | J16: =DATE(I16,H16,G16) -> #VALUE! | K16: =DATEDIF(J16,$J$5,"Y") -> #VALUE! | L16: NO
A17: 11 | F17: =MID(B17,11,1) | G17: =MID(B17,9,2) | H17: =MID(B17,7,2) | I17: =MID(B17,5,2)+2000 -> #VALUE! | J17: =DATE(I17,H17,G17) -> #VALUE! | K17: =DATEDIF(J17,$J$5,"Y") -> #VALUE! | L17: NO
A18: 12 | F18: =MID(B18,11,1) | G18: =MID(B18,9,2) | H18: =MID(B18,7,2) | I18: =MID(B18,5,2)+2000 -> #VALUE! | J18: =DATE(I18,H18,G18) -> #VALUE! | K18: =DATEDIF(J18,$J$5,"Y") -> #VALUE! | L18: NO
A19: 13 | F19: =MID(B19,11,1) | G19: =MID(B19,9,2) | H19: =MID(B19,7,2) | I19: =MID(B19,5,2)+2000 -> #VALUE! | J19: =DATE(I19,H19,G19) -> #VALUE! | K19: =DATEDIF(J19,$J$5,"Y") -> #VALUE! | L19: NO
A20: 14 | F20: =MID(B20,11,1) | G20: =MID(B20,9,2) | H20: =MID(B20,7,2) | I20: =MID(B20,5,2)+2000 -> #VALUE! | J20: =DATE(I20,H20,G20) -> #VALUE! | K20: =DATEDIF(J20,$J$5,"Y") -> #VALUE! | L20: NO
A21: 15 | F21: =MID(B21,11,1) | G21: =MID(B21,9,2) | H21: =MID(B21,7,2) | I21: =MID(B21,5,2)+2000 -> #VALUE! | J21: =DATE(I21,H21,G21) -> #VALUE! | K21: =DATEDIF(J21,$J$5,"Y") -> #VALUE! | L21: NO
A22: 16 | F22: =MID(B22,11,1) | G22: =MID(B22,9,2) | H22: =MID(B22,7,2) | I22: =MID(B22,5,2)+2000 -> #VALUE! | J22: =DATE(I22,H22,G22) -> #VALUE! | K22: =DATEDIF(J22,$J$5,"Y") -> #VALUE! | L22: NO
A23: 17 | F23: =MID(B23,11,1) | G23: =MID(B23,9,2) | H23: =MID(B23,7,2) | I23: =MID(B23,5,2)+2000 -> #VALUE! | J23: =DATE(I23,H23,G23) -> #VALUE! | K23: =DATEDIF(J23,$J$5,"Y") -> #VALUE! | L23: NO
A24: 18 | F24: =MID(B24,11,1) | G24: =MID(B24,9,2) | H24: =MID(B24,7,2) | I24: =MID(B24,5,2)+2000 -> #VALUE! | J24: =DATE(I24,H24,G24) -> #VALUE! | K24: =DATEDIF(J24,$J$5,"Y") -> #VALUE! | L24: NO
A25: 19 | F25: =MID(B25,11,1) | G25: =MID(B25,9,2) | H25: =MID(B25,7,2) | I25: =MID(B25,5,2)+2000 -> #VALUE! | J25: =DATE(I25,H25,G25) -> #VALUE! | K25: =DATEDIF(J25,$J$5,"Y") -> #VALUE! | L25: NO
... A41: 35 | F41: =MID(B41,11,1) | G41: =MID(B41,9,2) | H41: =MID(B41,7,2) | I41: =MID(B41,5,2)+2000 -> #VALUE! | J41: =DATE(I41,H41,G41) -> #VALUE! | K41: =DATEDIF(J41,$J$5,"Y") -> #VALUE! | L41: NO
A42: 36 | F42: =MID(B42,11,1) | G42: =MID(B42,9,2)
A43: 37 | F43: =MID(B43,11,1) | G43: =MID(B43,9,2)
A44: 38 | F44: =MID(B44,11,1) | G44: =MID(B44,9,2)
A45: 39 | F45: =MID(B45,11,1) | G45: =MID(B45,9,2)
A46: 40 | F46: =MID(B46,11,1) | G46: =MID(B46,9,2)
J47: MUJERES | K47: =COUNTIF(F7:F46, "M") -> 0
J48: HOMBRES | K48: =COUNTIF(F7:F46,"H") -> 0
J49: TOTAL | K49: =SUM(K47:K48) -> 0

Sheet Concen 3ro.
J1: ESTADÍSTICA DE GRUPO
F3: ESCUELA PRIMARIA
F4: CICLO ESCOLAR 2026-2027
C5: GRADO 3º | G5: EDADES | I5: AL | J5: 46266
C6: 5 AÑOS | D6: 6 AÑOS | E6: 7 AÑOS | F6: 8 AÑOS | G6: 9 AÑOS | H6: 10 AÑOS | I6: 11 AÑOS | J6: 12 AÑOS | K6: 13 AÑOS | L6: 14 AÑOS | M6: 15 AÑOS | N6: TOTAL
B7: NUEVO ING. | C7: ='3 A '!O7+'3 B'!O7 -> 0 | D7: ='3 A '!P7+'3 B'!P7 -> 0 | E7: ='3 A '!Q7+'3 B'!Q7 -> 0 | F7: ='3 A '!R7+'3 B'!R7 -> 0 | G7: ='3 A '!S7+'3 B'!S7 -> 0 | H7: ='3 A '!T7+'3 B'!T7 -> 0 | I7: ='3 A '!U7+'3 B'!U7 -> 0 | J7: ='3 A '!V7+'3 B'!V7 -> 0 | ... N7: ='3 A '!Z7+'3 B'!Z7 -> 0
A8: HOMBRES | B8: REPETIDORES | C8: ='3 A '!O8+'3 B'!O8 -> 0 | D8: ='3 A '!P8+'3 B'!P8 -> 0 | E8: ='3 A '!Q8+'3 B'!Q8 -> 0 | F8: ='3 A '!R8+'3 B'!R8 -> 0 | G8: ='3 A '!S8+'3 B'!S8 -> 0 | H8: ='3 A '!T8+'3 B'!T8 -> 0 | I8: ='3 A '!U8+'3 B'!U8 -> 0 | J8: ='3 A '!V8+'3 B'!V8 -> 0 | ... N8: ='3 A '!Z8+'3 B'!Z8 -> 0
C9: 5 AÑOS | D9: 6 AÑOS | E9: 7 AÑOS | F9: 8 AÑOS | G9: 9 AÑOS | H9: 10 AÑOS | I9: 11 AÑOS | J9: 12 AÑOS | K9: 13 AÑOS | L9: 14 AÑOS | M9: 15 AÑOS | N9: TOTAL
B10: NUEVO ING. | C10: ='3 A '!O10+'3 B'!O10 -> 0 | D10: ='3 A '!P10+'3 B'!P10 -> 0 | E10: ='3 A '!Q10+'3 B'!Q10 -> 0 | F10: ='3 A '!R10+'3 B'!R10 -> 0 | G10: ='3 A '!S10+'3 B'!S10 -> 0 | H10: ='3 A '!T10+'3 B'!T10 -> 0 | I10: ='3 A '!U10+'3 B'!U10 -> 0 | J10: ='3 A '!V10+'3 B'!V10 -> 0 | ... N10: ='3 A '!Z10+'3 B'!Z10 -> 0
A11: MUJERES | B11: REPETIDORES | C11: ='3 A '!O11+'3 B'!O11 -> 0 | D11: ='3 A '!P11+'3 B'!P11 -> 0 | E11: ='3 A '!Q11+'3 B'!Q11 -> 0 | F11: ='3 A '!R11+'3 B'!R11 -> 0 | G11: ='3 A '!S11+'3 B'!S11 -> 0 | H11: ='3 A '!T11+'3 B'!T11 -> 0 | I11: ='3 A '!U11+'3 B'!U11 -> 0 | J11: ='3 A '!V11+'3 B'!V11 -> 0 | ... N11: ='3 A '!Z11+'3 B'!Z11 -> 0
B13: SUBTOTAL | C13: ='3 A '!O13+'3 B'!O13 -> 0 | D13: ='3 A '!P13+'3 B'!P13 -> 0 | E13: ='3 A '!Q13+'3 B'!Q13 -> 0 | F13: ='3 A '!R13+'3 B'!R13 -> 0 | G13: ='3 A '!S13+'3 B'!S13 -> 0 | H13: ='3 A '!T13+'3 B'!T13 -> 0 | I13: ='3 A '!U13+'3 B'!U13 -> 0 | J13: ='3 A '!V13+'3 B'!V13 -> 0 | ... N13: ='3 A '!Z13+'3 B'!Z13 -> 0

Sheet 4 A
J1: ESTADÍSTICA DE GRUPO
F3: ESCUELA PRIMARIA | M3: ESPACIOS A LLENAR POR EL DOCENTE, EL RESTO ES AUTOMATIZADO.
F4: CICLO ESCOLAR 2026-2027
C5: GRADO 4º GRUPO " A " | G5: EDADES | I5: AL | J5: 46266
A6: Nº | B6: CURP | C6: NOMBRE DEL ALUMNO | F6: SEXO | G6: DIA | H6: MES | I6: AÑO | J6: FECHA_NAC | K6: EDAD | L6: REPETIDOR | O6: 5 AÑOS | P6: 6 AÑOS | Q6: 7 AÑOS | R6: 8 AÑOS | S6: 9 AÑOS | T6: 10 AÑOS | U6: 11 AÑOS | V6: 12 AÑOS | W6: 13 AÑOS | X6: 14 AÑOS | Y6: 15 AÑOS | Z6: TOTAL
A7: 1 | F7: =MID(B7,11,1) | G7: =MID(B7,9,2) | H7: =MID(B7,7,2) | I7: =MID(B7,5,2)+2000 -> #VALUE! | J7: =DATE(I7,H7,G7) -> #VALUE! | K7: =DATEDIF(J7,$J$5,"Y") -> #VALUE! | L7: NO | N7: NUEVO ING. | O7: =COUNTIFS($F$7:$F$46,"H",$K$7:$K$46,5,$L$7:$L$46,"NO") -> 0 | P7: =COUNTIFS($F$7:$F$46,"H",$K$7:$K$46,6,$L$7:$L$46,"NO") -> 0 | Q7: =COUNTIFS($F$7:$F$46,"H",$K$7:$K$46,7,$L$7:$L$46,"NO") -> 0 | R7: =COUNTIFS($F$7:$F$46,"H",$K$7:$K$46,8,$L$7:$L$46,"NO") -> 0 | S7: =COUNTIFS($F$7:$F$46,"H",$K$7:$K$46,9,$L$7:$L$46,"NO") -> 0 | T7: =COUNTIFS($F$7:$F$46,"H",$K$7:$K$46,10,$L$7:$L$46,"NO") -> 0 | U7: =COUNTIFS($F$7:$F$46,"H",$K$7:$K$46,11,$L$7:$L$46,"NO") -> 0 | V7: =COUNTIFS($F$7:$F$46,"H",$K$7:$K$46,12,$L$7:$L$46,"NO") -> 0 | W7: =COUNTIFS($F$7:$F$46,"H",$K$7:$K$46,13,$L$7:$L$46,"NO") -> 0 | X7: =COUNTIFS($F$7:$F$46,"H",$K$7:$K$46,14,$L$7:$L$46,"NO") -> 0 | Y7: =COUNTIFS($F$7:$F$46,"H",$K$7:$K$46,15,$L$7:$L$46,"NO") -> 0 | Z7: =SUM(O7:Y7) -> 0
A8: 2 | F8: =MID(B8,11,1) | G8: =MID(B8,9,2) | H8: =MID(B8,7,2) | I8: =MID(B8,5,2)+2000 -> #VALUE! | J8: =DATE(I8,H8,G8) -> #VALUE! | K8: =DATEDIF(J8,$J$5,"Y") -> #VALUE! | L8: NO | M8: HOMBRES | N8: REPETIDORES | O8: =COUNTIFS($F$7:$F$46,"H",$K$7:$K$46,5,$L$7:$L$46,"SI") -> 0 | P8: =COUNTIFS($F$7:$F$46,"H",$K$7:$K$46,6,$L$7:$L$46,"SI") -> 0 | Q8: =COUNTIFS($F$7:$F$46,"H",$K$7:$K$46,7,$L$7:$L$46,"SI") -> 0 | R8: =COUNTIFS($F$7:$F$46,"H",$K$7:$K$46,8,$L$7:$L$46,"SI") -> 0 | S8: =COUNTIFS($F$7:$F$46,"H",$K$7:$K$46,9,$L$7:$L$46,"SI") -> 0 | T8: =COUNTIFS($F$7:$F$46,"H",$K$7:$K$46,10,$L$7:$L$46,"SI") -> 0 | U8: =COUNTIFS($F$7:$F$46,"H",$K$7:$K$46,11,$L$7:$L$46,"SI") -> 0 | V8: =COUNTIFS($F$7:$F$46,"H",$K$7:$K$46,12,$L$7:$L$46,"SI") -> 0 | W8: =COUNTIFS($F$7:$F$46,"H",$K$7:$K$46,13,$L$7:$L$46,"SI") -> 0 | X8: =COUNTIFS($F$7:$F$46,"H",$K$7:$K$46,14,$L$7:$L$46,"SI") -> 0 | Y8: =COUNTIFS($F$7:$F$46,"H",$K$7:$K$46,15,$L$7:$L$46,"SI") -> 0 | Z8: =SUM(O8:Y8) -> 0
A9: 3 | F9: =MID(B9,11,1) | G9: =MID(B9,9,2) | H9: =MID(B9,7,2) | I9: =MID(B9,5,2)+2000 -> #VALUE! | J9: =DATE(I9,H9,G9) -> #VALUE! | K9: =DATEDIF(J9,$J$5,"Y") -> #VALUE! | L9: NO | O9: 5 AÑOS | P9: 6 AÑOS | Q9: 7 AÑOS | R9: 8 AÑOS | S9: 9 AÑOS | T9: 10 AÑOS | U9: 11 AÑOS | V9: 12 AÑOS | W9: 13 AÑOS | X9: 14 AÑOS | Y9: 15 AÑOS | Z9: TOTAL
